Workbook
Name man: H!$C$32
Name relaxf: H!$F$3
Name resist: H!$C$26
Name So: H!$C$29
Name well: qext!$C$6
Name width: H!$C$24

Sheet H
A1: Head distribution | E1: Calculations | G1: iterations | H1: =1+H1 -> 85740 | J1: Water Balance Groundwater
E2: improvement | F2: =G2 -> 8.6616212 | G2: =M10 -> 8.6616209 | H2: =F2-G2 -> 2.2002428e-07 | K2: IN | L2: OUT | M2: diff
A3: length | B3: =SUM(kd!C8:L8) -> 1000 | E3: relaxf | F3: 1.9 | J3: recharge | K3: =qext!C4 -> 285 | M3: =ABS(K3)-ABS(L3) -> 285
A4: width | B4: =SUM(kd!A10:A19) -> 100 | J4: boundary | K4: =wbal!E26 -> 0 | L4: =wbal!E27 -> -3.8552355 | M4: =ABS(K4)-ABS(L4) -> -3.8552355
J5: well | L5: =well -> 0 | M5: =ABS(K5)-ABS(L5) -> 0
J6: ow-grw exch | K6: =wbal!G27 -> 0 | L6: =wbal!G26 -> -281.14458 | M6: =ABS(K6)-ABS(L6) -> -281.14458
J7: total | K7: =SUM(K3:K6) -> 285 | L7: =SUM(L3:L6) -> -284.99982 | M7: =ABS(K7)-ABS(L7) -> 0.0001817252
B8: y | C8: 0 | D8: =C8+kd!C8 -> 100 | E8: =D8+kd!D8 -> 200 | F8: =E8+kd!E8 -> 300 | G8: =F8+kd!F8 -> 400 | H8: =G8+kd!G8 -> 500 | I8: =H8+kd!H8 -> 600 | J8: =I8+kd!I8 -> 700 | K8: =J8+kd!J8 -> 800 | ... M8: =L8+kd!L8 -> 1000
A9: x
A10: 0 | C10: 6 | D10: =(1-relaxf)*D10+relaxf*(D9*north!D10+H!E10*east!D10+H!D11*south!D10+H!C10*west!D10+qext!D10)/(north!D10+east!D10+south!D10+west!D10) -> 6.1751705 | E10: =(1-relaxf)*E10+relaxf*(E9*north!E10+H!F10*east!E10+H!E11*south!E10+H!D10*west!E10+qext!E10)/(north!E10+east!E10+south!E10+west!E10) -> 6.4342356 | F10: =(1-relaxf)*F10+relaxf*(F9*north!F10+H!G10*east!F10+H!F11*south!F10+H!E10*west!F10+qext!F10)/(north!F10+east!F10+south!F10+west!F10) -> 6.7244348 | G10: =(1-relaxf)*G10+relaxf*(G9*north!G10+H!H10*east!G10+H!G11*south!G10+H!F10*west!G10+qext!G10)/(north!G10+east!G10+south!G10+west!G10) -> 7.0220769 | H10: =(1-relaxf)*H10+relaxf*(H9*north!H10+H!I10*east!H10+H!H11*south!H10+H!G10*west!H10+qext!H10)/(north!H10+east!H10+south!H10+west!H10) -> 7.3213772 | I10: =(1-relaxf)*I10+relaxf*(I9*north!I10+H!J10*east!I10+H!I11*south!I10+H!H10*west!I10+qext!I10)/(north!I10+east!I10+south!I10+west!I10) -> 7.6208074 | J10: =(1-relaxf)*J10+relaxf*(J9*north!J10+H!K10*east!J10+H!J11*south!J10+H!I10*west!J10+qext!J10)/(north!J10+east!J10+south!J10+west!J10) -> 7.9191741 | K10: =(1-relaxf)*K10+relaxf*(K9*north!K10+H!L10*east!K10+H!K11*south!K10+H!J10*west!K10+qext!K10)/(north!K10+east!K10+south!K10+west!K10) -> 8.2125337 | ... M10: =(1-relaxf)*M10+relaxf*(M9*north!M10+H!N10*east!M10+H!M11*south!M10+H!L10*west!M10+qext!M10)/(north!M10+east!M10+south!M10+west!M10) -> 8.6616207
A11: =A10+kd!A10 -> 10 | C11: 6 | D11: =(1-relaxf)*D11+relaxf*(D10*north!D11+H!E11*east!D11+H!D12*south!D11+H!C11*west!D11+qext!D11)/(north!D11+east!D11+south!D11+west!D11) -> 6.1697511 | E11: =(1-relaxf)*E11+relaxf*(E10*north!E11+H!F11*east!E11+H!E12*south!E11+H!D11*west!E11+qext!E11)/(north!E11+east!E11+south!E11+west!E11) -> 6.42908 | F11: =(1-relaxf)*F11+relaxf*(F10*north!F11+H!G11*east!F11+H!F12*south!F11+H!E11*west!F11+qext!F11)/(north!F11+east!F11+south!F11+west!F11) -> 6.7193976 | G11: =(1-relaxf)*G11+relaxf*(G10*north!G11+H!H11*east!G11+H!G12*south!G11+H!F11*west!G11+qext!G11)/(north!G11+east!G11+south!G11+west!G11) -> 7.0170686 | H11: =(1-relaxf)*H11+relaxf*(H10*north!H11+H!I11*east!H11+H!H12*south!H11+H!G11*west!H11+qext!H11)/(north!H11+east!H11+south!H11+west!H11) -> 7.3163765 | I11: =(1-relaxf)*I11+relaxf*(I10*north!I11+H!J11*east!I11+H!I12*south!I11+H!H11*west!I11+qext!I11)/(north!I11+east!I11+south!I11+west!I11) -> 7.6158128 | J11: =(1-relaxf)*J11+relaxf*(J10*north!J11+H!K11*east!J11+H!J12*south!J11+H!I11*west!J11+qext!J11)/(north!J11+east!J11+south!J11+west!J11) -> 7.9141992 | K11: =(1-relaxf)*K11+relaxf*(K10*north!K11+H!L11*east!K11+H!K12*south!K11+H!J11*west!K11+qext!K11)/(north!K11+east!K11+south!K11+west!K11) -> 8.207643 | ... M11: =(1-relaxf)*M11+relaxf*(M10*north!M11+H!N11*east!M11+H!M12*south!M11+H!L11*west!M11+qext!M11)/(north!M11+east!M11+south!M11+west!M11) -> 8.6583968
A12: =A11+kd!A11 -> 20 | C12: 6 | D12: =(1-relaxf)*D12+relaxf*(D11*north!D12+H!E12*east!D12+H!D13*south!D12+H!C12*west!D12+qext!D12)/(north!D12+east!D12+south!D12+west!D12) -> 6.1534358 | E12: =(1-relaxf)*E12+relaxf*(E11*north!E12+H!F12*east!E12+H!E13*south!E12+H!D12*west!E12+qext!E12)/(north!E12+east!E12+south!E12+west!E12) -> 6.4136145 | F12: =(1-relaxf)*F12+relaxf*(F11*north!F12+H!G12*east!F12+H!F13*south!F12+H!E12*west!F12+qext!F12)/(north!F12+east!F12+south!F12+west!F12) -> 6.7042869 | G12: =(1-relaxf)*G12+relaxf*(G11*north!G12+H!H12*east!G12+H!G13*south!G12+H!F12*west!G12+qext!G12)/(north!G12+east!G12+south!G12+west!G12) -> 7.0020439 | H12: =(1-relaxf)*H12+relaxf*(H11*north!H12+H!I12*east!H12+H!H13*south!H12+H!G12*west!H12+qext!H12)/(north!H12+east!H12+south!H12+west!H12) -> 7.3013746 | I12: =(1-relaxf)*I12+relaxf*(I11*north!I12+H!J12*east!I12+H!I13*south!I12+H!H12*west!I12+qext!I12)/(north!I12+east!I12+south!I12+west!I12) -> 7.6008286 | J12: =(1-relaxf)*J12+relaxf*(J11*north!J12+H!K12*east!J12+H!J13*south!J12+H!I12*west!J12+qext!J12)/(north!J12+east!J12+south!J12+west!J12) -> 7.8992736 | K12: =(1-relaxf)*K12+relaxf*(K11*north!K12+H!L12*east!K12+H!K13*south!K12+H!J12*west!K12+qext!K12)/(north!K12+east!K12+south!K12+west!K12) -> 8.1929682 | ... M12: =(1-relaxf)*M12+relaxf*(M11*north!M12+H!N12*east!M12+H!M13*south!M12+H!L12*west!M12+qext!M12)/(north!M12+east!M12+south!M12+west!M12) -> 8.6487508
A13: =A12+kd!A12 -> 30 | C13: 6 | D13: =(1-relaxf)*D13+relaxf*(D12*north!D13+H!E13*east!D13+H!D14*south!D13+H!C13*west!D13+qext!D13)/(north!D13+east!D13+south!D13+west!D13) -> 6.1260532 | E13: =(1-relaxf)*E13+relaxf*(E12*north!E13+H!F13*east!E13+H!E14*south!E13+H!D13*west!E13+qext!E13)/(north!E13+east!E13+south!E13+west!E13) -> 6.387844 | F13: =(1-relaxf)*F13+relaxf*(F12*north!F13+H!G13*east!F13+H!F14*south!F13+H!E13*west!F13+qext!F13)/(north!F13+east!F13+south!F13+west!F13) -> 6.6791052 | G13: =(1-relaxf)*G13+relaxf*(G12*north!G13+H!H13*east!G13+H!G14*south!G13+H!F13*west!G13+qext!G13)/(north!G13+east!G13+south!G13+west!G13) -> 6.9770035 | H13: =(1-relaxf)*H13+relaxf*(H12*north!H13+H!I13*east!H13+H!H14*south!H13+H!G13*west!H13+qext!H13)/(north!H13+east!H13+south!H13+west!H13) -> 7.2763714 | I13: =(1-relaxf)*I13+relaxf*(I12*north!I13+H!J13*east!I13+H!I14*south!I13+H!H13*west!I13+qext!I13)/(north!I13+east!I13+south!I13+west!I13) -> 7.5758544 | J13: =(1-relaxf)*J13+relaxf*(J12*north!J13+H!K13*east!J13+H!J14*south!J13+H!I13*west!J13+qext!J13)/(north!J13+east!J13+south!J13+west!J13) -> 7.8743955 | K13: =(1-relaxf)*K13+relaxf*(K12*north!K13+H!L13*east!K13+H!K14*south!K13+H!J13*west!K13+qext!K13)/(north!K13+east!K13+south!K13+west!K13) -> 8.1685012 | ... M13: =(1-relaxf)*M13+relaxf*(M12*north!M13+H!N13*east!M13+H!M14*south!M13+H!L13*west!M13+qext!M13)/(north!M13+east!M13+south!M13+west!M13) -> 8.6327619
A14: =A13+kd!A13 -> 40 | C14: 6 | D14: =(1-relaxf)*D14+relaxf*(D13*north!D14+H!E14*east!D14+H!D15*south!D14+H!C14*west!D14+qext!D14)/(north!D14+east!D14+south!D14+west!D14) -> 6.0873131 | E14: =(1-relaxf)*E14+relaxf*(E13*north!E14+H!F14*east!E14+H!E15*south!E14+H!D14*west!E14+qext!E14)/(north!E14+east!E14+south!E14+west!E14) -> 6.3517788 | F14: =(1-relaxf)*F14+relaxf*(F13*north!F14+H!G14*east!F14+H!F15*south!F14+H!E14*west!F14+qext!F14)/(north!F14+east!F14+south!F14+west!F14) -> 6.6438573 | G14: =(1-relaxf)*G14+relaxf*(G13*north!G14+H!H14*east!G14+H!G15*south!G14+H!F14*west!G14+qext!G14)/(north!G14+east!G14+south!G14+west!G14) -> 6.9419484 | H14: =(1-relaxf)*H14+relaxf*(H13*north!H14+H!I14*east!H14+H!H15*south!H14+H!G14*west!H14+qext!H14)/(north!H14+east!H14+south!H14+west!H14) -> 7.2413671 | I14: =(1-relaxf)*I14+relaxf*(I13*north!I14+H!J14*east!I14+H!I15*south!I14+H!H14*west!I14+qext!I14)/(north!I14+east!I14+south!I14+west!I14) -> 7.5408897 | J14: =(1-relaxf)*J14+relaxf*(J13*north!J14+H!K14*east!J14+H!J15*south!J14+H!I14*west!J14+qext!J14)/(north!J14+east!J14+south!J14+west!J14) -> 7.8395619 | K14: =(1-relaxf)*K14+relaxf*(K13*north!K14+H!L14*east!K14+H!K15*south!K14+H!J14*west!K14+qext!K14)/(north!K14+east!K14+south!K14+west!K14) -> 8.1342282 | ... M14: =(1-relaxf)*M14+relaxf*(M13*north!M14+H!N14*east!M14+H!M15*south!M14+H!L14*west!M14+qext!M14)/(north!M14+east!M14+south!M14+west!M14) -> 8.6105644
A15: =A14+kd!A14 -> 50 | C15: 6 | D15: =(1-relaxf)*D15+relaxf*(D14*north!D15+H!E15*east!D15+H!D16*south!D15+H!C15*west!D15+qext!D15+D39*D24*D25/D26)/(north!D15+east!D15+south!D15+west!D15+D24*D25/D26) -> 6.0368015 | E15: =(1-relaxf)*E15+relaxf*(E14*north!E15+H!F15*east!E15+H!E16*south!E15+H!D15*west!E15+qext!E15+E39*E24*E25/E26)/(north!E15+east!E15+south!E15+west!E15+E24*E25/E26) -> 6.3054375 | F15: =(1-relaxf)*F15+relaxf*(F14*north!F15+H!G15*east!F15+H!F16*south!F15+H!E15*west!F15+qext!F15+F39*F24*F25/F26)/(north!F15+east!F15+south!F15+west!F15+F24*F25/F26) -> 6.5985492 | G15: =(1-relaxf)*G15+relaxf*(G14*north!G15+H!H15*east!G15+H!G16*south!G15+H!F15*west!G15+qext!G15+G39*G24*G25/G26)/(north!G15+east!G15+south!G15+west!G15+G24*G25/G26) -> 6.89688 | H15: =(1-relaxf)*H15+relaxf*(H14*north!H15+H!I15*east!H15+H!H16*south!H15+H!G15*west!H15+qext!H15+H39*H24*H25/H26)/(north!H15+east!H15+south!H15+west!H15+H24*H25/H26) -> 7.1963617 | I15: =(1-relaxf)*I15+relaxf*(I14*north!I15+H!J15*east!I15+H!I16*south!I15+H!H15*west!I15+qext!I15+I39*I24*I25/I26)/(north!I15+east!I15+south!I15+west!I15+I24*I25/I26) -> 7.4959336 | J15: =(1-relaxf)*J15+relaxf*(J14*north!J15+H!K15*east!J15+H!J16*south!J15+H!I15*west!J15+qext!J15+J39*J24*J25/J26)/(north!J15+east!J15+south!J15+west!J15+J24*J25/J26) -> 7.7947683 | K15: =(1-relaxf)*K15+relaxf*(K14*north!K15+H!L15*east!K15+H!K16*south!K15+H!J15*west!K15+qext!K15+K39*K24*K25/K26)/(north!K15+east!K15+south!K15+west!K15+K24*K25/K26) -> 8.0901308 | ... M15: =(1-relaxf)*M15+relaxf*(M14*north!M15+H!N15*east!M15+H!M16*south!M15+H!L15*west!M15+qext!M15+M39*M24*M25/M26)/(north!M15+east!M15+south!M15+west!M15+M24*M25/M26) -> 8.5823514
A16: =A15+kd!A15 -> 60 | C16: 6 | D16: =(1-relaxf)*D16+relaxf*(D15*north!D16+H!E16*east!D16+H!D17*south!D16+H!C16*west!D16+qext!D16)/(north!D16+east!D16+south!D16+west!D16) -> 6.0873131 | E16: =(1-relaxf)*E16+relaxf*(E15*north!E16+H!F16*east!E16+H!E17*south!E16+H!D16*west!E16+qext!E16)/(north!E16+east!E16+south!E16+west!E16) -> 6.3517788 | F16: =(1-relaxf)*F16+relaxf*(F15*north!F16+H!G16*east!F16+H!F17*south!F16+H!E16*west!F16+qext!F16)/(north!F16+east!F16+south!F16+west!F16) -> 6.6438573 | G16: =(1-relaxf)*G16+relaxf*(G15*north!G16+H!H16*east!G16+H!G17*south!G16+H!F16*west!G16+qext!G16)/(north!G16+east!G16+south!G16+west!G16) -> 6.9419484 | H16: =(1-relaxf)*H16+relaxf*(H15*north!H16+H!I16*east!H16+H!H17*south!H16+H!G16*west!H16+qext!H16)/(north!H16+east!H16+south!H16+west!H16) -> 7.2413671 | I16: =(1-relaxf)*I16+relaxf*(I15*north!I16+H!J16*east!I16+H!I17*south!I16+H!H16*west!I16+qext!I16)/(north!I16+east!I16+south!I16+west!I16) -> 7.5408898 | J16: =(1-relaxf)*J16+relaxf*(J15*north!J16+H!K16*east!J16+H!J17*south!J16+H!I16*west!J16+qext!J16)/(north!J16+east!J16+south!J16+west!J16) -> 7.8395619 | K16: =(1-relaxf)*K16+relaxf*(K15*north!K16+H!L16*east!K16+H!K17*south!K16+H!J16*west!K16+qext!K16)/(north!K16+east!K16+south!K16+west!K16) -> 8.1342283 | ... M16: =(1-relaxf)*M16+relaxf*(M15*north!M16+H!N16*east!M16+H!M17*south!M16+H!L16*west!M16+qext!M16)/(north!M16+east!M16+south!M16+west!M16) -> 8.6105646
A17: =A16+kd!A16 -> 70 | C17: 6 | D17: =(1-relaxf)*D17+relaxf*(D16*north!D17+H!E17*east!D17+H!D18*south!D17+H!C17*west!D17+qext!D17)/(north!D17+east!D17+south!D17+west!D17) -> 6.1260532 | E17: =(1-relaxf)*E17+relaxf*(E16*north!E17+H!F17*east!E17+H!E18*south!E17+H!D17*west!E17+qext!E17)/(north!E17+east!E17+south!E17+west!E17) -> 6.387844 | F17: =(1-relaxf)*F17+relaxf*(F16*north!F17+H!G17*east!F17+H!F18*south!F17+H!E17*west!F17+qext!F17)/(north!F17+east!F17+south!F17+west!F17) -> 6.6791053 | G17: =(1-relaxf)*G17+relaxf*(G16*north!G17+H!H17*east!G17+H!G18*south!G17+H!F17*west!G17+qext!G17)/(north!G17+east!G17+south!G17+west!G17) -> 6.9770035 | H17: =(1-relaxf)*H17+relaxf*(H16*north!H17+H!I17*east!H17+H!H18*south!H17+H!G17*west!H17+qext!H17)/(north!H17+east!H17+south!H17+west!H17) -> 7.2763714 | I17: =(1-relaxf)*I17+relaxf*(I16*north!I17+H!J17*east!I17+H!I18*south!I17+H!H17*west!I17+qext!I17)/(north!I17+east!I17+south!I17+west!I17) -> 7.5758545 | J17: =(1-relaxf)*J17+relaxf*(J16*north!J17+H!K17*east!J17+H!J18*south!J17+H!I17*west!J17+qext!J17)/(north!J17+east!J17+south!J17+west!J17) -> 7.8743956 | K17: =(1-relaxf)*K17+relaxf*(K16*north!K17+H!L17*east!K17+H!K18*south!K17+H!J17*west!K17+qext!K17)/(north!K17+east!K17+south!K17+west!K17) -> 8.1685012 | ... M17: =(1-relaxf)*M17+relaxf*(M16*north!M17+H!N17*east!M17+H!M18*south!M17+H!L17*west!M17+qext!M17)/(north!M17+east!M17+south!M17+west!M17) -> 8.6327621
A18: =A17+kd!A17 -> 80 | C18: 6 | D18: =(1-relaxf)*D18+relaxf*(D17*north!D18+H!E18*east!D18+H!D19*south!D18+H!C18*west!D18+qext!D18)/(north!D18+east!D18+south!D18+west!D18) -> 6.1534359 | E18: =(1-relaxf)*E18+relaxf*(E17*north!E18+H!F18*east!E18+H!E19*south!E18+H!D18*west!E18+qext!E18)/(north!E18+east!E18+south!E18+west!E18) -> 6.4136145 | F18: =(1-relaxf)*F18+relaxf*(F17*north!F18+H!G18*east!F18+H!F19*south!F18+H!E18*west!F18+qext!F18)/(north!F18+east!F18+south!F18+west!F18) -> 6.7042868 | G18: =(1-relaxf)*G18+relaxf*(G17*north!G18+H!H18*east!G18+H!G19*south!G18+H!F18*west!G18+qext!G18)/(north!G18+east!G18+south!G18+west!G18) -> 7.0020438 | H18: =(1-relaxf)*H18+relaxf*(H17*north!H18+H!I18*east!H18+H!H19*south!H18+H!G18*west!H18+qext!H18)/(north!H18+east!H18+south!H18+west!H18) -> 7.3013745 | I18: =(1-relaxf)*I18+relaxf*(I17*north!I18+H!J18*east!I18+H!I19*south!I18+H!H18*west!I18+qext!I18)/(north!I18+east!I18+south!I18+west!I18) -> 7.6008285 | J18: =(1-relaxf)*J18+relaxf*(J17*north!J18+H!K18*east!J18+H!J19*south!J18+H!I18*west!J18+qext!J18)/(north!J18+east!J18+south!J18+west!J18) -> 7.8992735 | K18: =(1-relaxf)*K18+relaxf*(K17*north!K18+H!L18*east!K18+H!K19*south!K18+H!J18*west!K18+qext!K18)/(north!K18+east!K18+south!K18+west!K18) -> 8.1929682 | ... M18: =(1-relaxf)*M18+relaxf*(M17*north!M18+H!N18*east!M18+H!M19*south!M18+H!L18*west!M18+qext!M18)/(north!M18+east!M18+south!M18+west!M18) -> 8.648751
A19: =A18+kd!A18 -> 90 | C19: 6 | D19: =(1-relaxf)*D19+relaxf*(D18*north!D19+H!E19*east!D19+H!D20*south!D19+H!C19*west!D19+qext!D19)/(north!D19+east!D19+south!D19+west!D19) -> 6.1697511 | E19: =(1-relaxf)*E19+relaxf*(E18*north!E19+H!F19*east!E19+H!E20*south!E19+H!D19*west!E19+qext!E19)/(north!E19+east!E19+south!E19+west!E19) -> 6.4290801 | F19: =(1-relaxf)*F19+relaxf*(F18*north!F19+H!G19*east!F19+H!F20*south!F19+H!E19*west!F19+qext!F19)/(north!F19+east!F19+south!F19+west!F19) -> 6.7193976 | G19: =(1-relaxf)*G19+relaxf*(G18*north!G19+H!H19*east!G19+H!G20*south!G19+H!F19*west!G19+qext!G19)/(north!G19+east!G19+south!G19+west!G19) -> 7.0170685 | H19: =(1-relaxf)*H19+relaxf*(H18*north!H19+H!I19*east!H19+H!H20*south!H19+H!G19*west!H19+qext!H19)/(north!H19+east!H19+south!H19+west!H19) -> 7.3163765 | I19: =(1-relaxf)*I19+relaxf*(I18*north!I19+H!J19*east!I19+H!I20*south!I19+H!H19*west!I19+qext!I19)/(north!I19+east!I19+south!I19+west!I19) -> 7.6158127 | J19: =(1-relaxf)*J19+relaxf*(J18*north!J19+H!K19*east!J19+H!J20*south!J19+H!I19*west!J19+qext!J19)/(north!J19+east!J19+south!J19+west!J19) -> 7.9141991 | K19: =(1-relaxf)*K19+relaxf*(K18*north!K19+H!L19*east!K19+H!K20*south!K19+H!J19*west!K19+qext!K19)/(north!K19+east!K19+south!K19+west!K19) -> 8.207643 | ... M19: =(1-relaxf)*M19+relaxf*(M18*north!M19+H!N19*east!M19+H!M20*south!M19+H!L19*west!M19+qext!M19)/(north!M19+east!M19+south!M19+west!M19) -> 8.6583971
A20: =A19+kd!A19 -> 100 | C20: 6 | D20: =(1-relaxf)*D20+relaxf*(D19*north!D20+H!E20*east!D20+H!D21*south!D20+H!C20*west!D20+qext!D20)/(north!D20+east!D20+south!D20+west!D20) -> 6.1751706 | E20: =(1-relaxf)*E20+relaxf*(E19*north!E20+H!F20*east!E20+H!E21*south!E20+H!D20*west!E20+qext!E20)/(north!E20+east!E20+south!E20+west!E20) -> 6.4342357 | F20: =(1-relaxf)*F20+relaxf*(F19*north!F20+H!G20*east!F20+H!F21*south!F20+H!E20*west!F20+qext!F20)/(north!F20+east!F20+south!F20+west!F20) -> 6.7244348 | G20: =(1-relaxf)*G20+relaxf*(G19*north!G20+H!H20*east!G20+H!G21*south!G20+H!F20*west!G20+qext!G20)/(north!G20+east!G20+south!G20+west!G20) -> 7.0220768 | H20: =(1-relaxf)*H20+relaxf*(H19*north!H20+H!I20*east!H20+H!H21*south!H20+H!G20*west!H20+qext!H20)/(north!H20+east!H20+south!H20+west!H20) -> 7.3213771 | I20: =(1-relaxf)*I20+relaxf*(I19*north!I20+H!J20*east!I20+H!I21*south!I20+H!H20*west!I20+qext!I20)/(north!I20+east!I20+south!I20+west!I20) -> 7.6208074 | J20: =(1-relaxf)*J20+relaxf*(J19*north!J20+H!K20*east!J20+H!J21*south!J20+H!I20*west!J20+qext!J20)/(north!J20+east!J20+south!J20+west!J20) -> 7.9191741 | K20: =(1-relaxf)*K20+relaxf*(K19*north!K20+H!L20*east!K20+H!K21*south!K20+H!J20*west!K20+qext!K20)/(north!K20+east!K20+south!K20+west!K20) -> 8.2125337 | ... M20: =(1-relaxf)*M20+relaxf*(M19*north!M20+H!N20*east!M20+H!M21*south!M20+H!L20*west!M20+qext!M20)/(north!M20+east!M20+south!M20+west!M20) -> 8.6616212
B24: width | C24: 5 | D24: =width -> 5 | E24: =width -> 5 | F24: =width -> 5 | G24: =width -> 5 | H24: =width -> 5 | I24: =width -> 5 | J24: =width -> 5 | K24: =width -> 5 | ... M24: =width -> 5 | N24: m
B25: length | C25: =(kd!B8+kd!C8)/2 -> 50 | D25: =(kd!C8+kd!D8)/2 -> 100 | E25: =(kd!D8+kd!E8)/2 -> 100 | F25: =(kd!E8+kd!F8)/2 -> 100 | G25: =(kd!F8+kd!G8)/2 -> 100 | H25: =(kd!G8+kd!H8)/2 -> 100 | I25: =(kd!H8+kd!I8)/2 -> 100 | J25: =(kd!I8+kd!J8)/2 -> 100 | ... M25: =(kd!L8+kd!M8)/2 -> 50 | N25: m
B26: resist | C26: =5 -> 5 | D26: =5 -> 5 | E26: =5 -> 5 | F26: =5 -> 5 | G26: =5 -> 5 | H26: =5 -> 5 | I26: =5 -> 5 | J26: =5 -> 5 | ... M26: =5 -> 5 | N26: d
B27: d init | C27: 1 | D27: 1 | E27: 1 | F27: 1 | G27: 1 | H27: 1 | I27: 1 | J27: 1 | K27: 1 | L27: 1 | M27: 1 | N27: m
B29: slope | C29: 0.003 | D29: =So -> 0.003 | E29: =So -> 0.003 | F29: =So -> 0.003 | G29: =So -> 0.003 | H29: =So -> 0.003 | I29: =So -> 0.003 | J29: =So -> 0.003 | K29: =So -> 0.003 | ... M29: =So -> 0.003 | N29: m/m
B30: bottom | C30: 5 | D30: =C30+D29*(D8-C8) -> 5.3 | E30: =D30+E29*(E8-D8) -> 5.6 | F30: =E30+F29*(F8-E8) -> 5.9 | G30: =F30+G29*(G8-F8) -> 6.2 | H30: =G30+H29*(H8-G8) -> 6.5 | I30: =H30+I29*(I8-H8) -> 6.8 | J30: =I30+J29*(J8-I8) -> 7.1 | K30: =J30+K29*(K8-J8) -> 7.4 | ... M30: =L30+M29*(M8-L8) -> 8 | N30: m
O31: Qinit, d=1m
B32: manning | C32: 0.004
B33: leakage | D33: =-(D39-D15)/resist*width*D25 -> 34.002454 | E33: =-(E39-E15)/resist*width*E25 -> 30.878224 | F33: =-(F39-F15)/resist*width*F25 -> 30.200507 | G33: =-(G39-G15)/resist*width*G25 -> 30.044464 | H33: =-(H39-H15)/resist*width*H25 -> 30.003462 | I33: =-(I39-I15)/resist*width*I25 -> 29.971464 | J33: =-(J39-J15)/resist*width*J25 -> 29.865735 | K33: =-(K39-K15)/resist*width*K25 -> 29.412761 | ... M33: =-(M39-M15)/resist*width*M25 -> 9.3276862 | N33: m3/d
B34: Qppn | D34: =qext!$C$3*width*D25 -> 1.5 | E34: =qext!$C$3*width*E25 -> 1.5 | F34: =qext!$C$3*width*F25 -> 1.5 | G34: =qext!$C$3*width*G25 -> 1.5 | H34: =qext!$C$3*width*H25 -> 1.5 | I34: =qext!$C$3*width*I25 -> 1.5 | J34: =qext!$C$3*width*J25 -> 1.5 | K34: =qext!$C$3*width*K25 -> 1.5 | ... M34: =qext!$C$3*width*M25 -> 0.75
B35: Qstream | C35: =D35+C33 -> 69415.395 | D35: =E35+D33+D34 -> 69415.395 | E35: =F35+E33+E34 -> 69379.892 | F35: =G35+F33+F34 -> 69347.514 | G35: =H35+G33+G34 -> 69315.814 | H35: =I35+H33+H34 -> 69284.269 | I35: =J35+I33+I34 -> 69252.766 | J35: =K35+J33+J34 -> 69221.294 | K35: =L35+K33+K34 -> 69189.928 | ... M35: =N35+M33+M34 -> 69130.078 | N35: =34560*2 -> 69120 | O35: upstream inflow | Q35: m3/d
B37: initialize | C37: =C37+1 -> 161
B38: d calc | C38: =D38 -> 0.39677699 | D38: =IF($C$37>25,((D35/86400)*man/(width*D29))^0.6,D27) -> 0.39677699 | E38: =IF($C$37>25,((E35/86400)*man/(width*E29))^0.6,E27) -> 0.39665521 | F38: =IF($C$37>25,((F35/86400)*man/(width*F29))^0.6,F27) -> 0.39654414 | G38: =IF($C$37>25,((G35/86400)*man/(width*G29))^0.6,G27) -> 0.39643536 | H38: =IF($C$37>25,((H35/86400)*man/(width*H29))^0.6,H27) -> 0.39632711 | I38: =IF($C$37>25,((I35/86400)*man/(width*I29))^0.6,I27) -> 0.39621897 | J38: =IF($C$37>25,((J35/86400)*man/(width*J29))^0.6,J27) -> 0.39611093 | K38: =IF($C$37>25,((K35/86400)*man/(width*K29))^0.6,K27) -> 0.39600322 | ... M38: =IF($C$37>25,((M35/86400)*man/(width*M29))^0.6,M27) -> 0.39579766
B39: Hstream | C39: =C30+C38 -> 5.396777 | D39: =D30+D38 -> 5.696777 | E39: =E30+E38 -> 5.9966552 | F39: =F30+F38 -> 6.2965441 | G39: =G30+G38 -> 6.5964354 | H39: =H30+H38 -> 6.8963271 | I39: =I30+I38 -> 7.196219 | J39: =J30+J38 -> 7.4961109 | ... M39: =M30+M38 -> 8.3957977 | N39: m
B42: Qstream | C42: =C35/86400 -> 0.80341892 | D42: =D35/86400 -> 0.80341892 | E42: =E35/86400 -> 0.80300801 | F42: =F35/86400 -> 0.80263327 | G42: =G35/86400 -> 0.80226636 | H42: =H35/86400 -> 0.80190126 | I42: =I35/86400 -> 0.80153664 | J42: =J35/86400 -> 0.80117238 | ... M42: =M35/86400 -> 0.80011664 | N42: m3/s

Sheet kd
A1: kD- field (m2/d) and domain dimensions
C7: length
A8: width | C8: 100 | D8: 100 | E8: 100 | F8: 100 | G8: 100 | H8: 100 | I8: 100 | J8: 100 | K8: 100 | L8: 100
A10: 10 | C10: 30 | D10: 30 | E10: 30 | F10: 30 | G10: 30 | H10: 30 | I10: 30 | J10: 30 | K10: 30 | L10: 30
A11: 10 | C11: 30 | D11: 30 | E11: 30 | F11: 30 | G11: 30 | H11: 30 | I11: 30 | J11: 30 | K11: 30 | L11: 30
A12: 10 | C12: 30 | D12: 30 | E12: 30 | F12: 30 | G12: 30 | H12: 30 | I12: 30 | J12: 30 | K12: 30 | L12: 30
A13: 10 | C13: 30 | D13: 30 | E13: 30 | F13: 30 | G13: 30 | H13: 30 | I13: 30 | J13: 30 | K13: 30 | L13: 30
A14: 10 | C14: 30 | D14: 30 | E14: 30 | F14: 30 | G14: 30 | H14: 30 | I14: 30 | J14: 30 | K14: 30 | L14: 30
A15: 10 | C15: 30 | D15: 30 | E15: 30 | F15: 30 | G15: 30 | H15: 30 | I15: 30 | J15: 30 | K15: 30 | L15: 30
A16: 10 | C16: 30 | D16: 30 | E16: 30 | F16: 30 | G16: 30 | H16: 30 | I16: 30 | J16: 30 | K16: 30 | L16: 30
A17: 10 | C17: 30 | D17: 30 | E17: 30 | F17: 30 | G17: 30 | H17: 30 | I17: 30 | J17: 30 | K17: 30 | L17: 30
A18: 10 | C18: 30 | D18: 30 | E18: 30 | F18: 30 | G18: 30 | H18: 30 | I18: 30 | J18: 30 | K18: 30 | L18: 30
A19: 10 | C19: 30 | D19: 30 | E19: 30 | F19: 30 | G19: 30 | H19: 30 | I19: 30 | J19: 30 | K19: 30 | L19: 30

Sheet qext
A1: external fluxes
B3: Recharge rate | C3: 0.003
B4: Total Recharge | C4: =SUM(C10:M20)-well -> 285
B6: well | C6: 0
C10: 0 | D10: =0.25*((kd!C$8+kd!D$8)*(kd!$A9+kd!$A10))*$C$3 -> 1.5 | E10: =0.25*((kd!D$8+kd!E$8)*(kd!$A9+kd!$A10))*$C$3 -> 1.5 | F10: =0.25*((kd!E$8+kd!F$8)*(kd!$A9+kd!$A10))*$C$3 -> 1.5 | G10: =0.25*((kd!F$8+kd!G$8)*(kd!$A9+kd!$A10))*$C$3 -> 1.5 | H10: =0.25*((kd!G$8+kd!H$8)*(kd!$A9+kd!$A10))*$C$3 -> 1.5 | I10: =0.25*((kd!H$8+kd!I$8)*(kd!$A9+kd!$A10))*$C$3 -> 1.5 | J10: =0.25*((kd!I$8+kd!J$8)*(kd!$A9+kd!$A10))*$C$3 -> 1.5 | K10: =0.25*((kd!J$8+kd!K$8)*(kd!$A9+kd!$A10))*$C$3 -> 1.5 | ... M10: =0.25*((kd!L$8+kd!M$8)*(kd!$A9+kd!$A10))*$C$3 -> 0.75
C11: 0 | D11: =0.25*((kd!C$8+kd!D$8)*(kd!$A10+kd!$A11))*$C$3 -> 3 | E11: =0.25*((kd!D$8+kd!E$8)*(kd!$A10+kd!$A11))*$C$3 -> 3 | F11: =0.25*((kd!E$8+kd!F$8)*(kd!$A10+kd!$A11))*$C$3 -> 3 | G11: =0.25*((kd!F$8+kd!G$8)*(kd!$A10+kd!$A11))*$C$3 -> 3 | H11: =0.25*((kd!G$8+kd!H$8)*(kd!$A10+kd!$A11))*$C$3 -> 3 | I11: =0.25*((kd!H$8+kd!I$8)*(kd!$A10+kd!$A11))*$C$3 -> 3 | J11: =0.25*((kd!I$8+kd!J$8)*(kd!$A10+kd!$A11))*$C$3 -> 3 | K11: =0.25*((kd!J$8+kd!K$8)*(kd!$A10+kd!$A11))*$C$3 -> 3 | ... M11: =0.25*((kd!L$8+kd!M$8)*(kd!$A10+kd!$A11))*$C$3 -> 1.5
C12: 0 | D12: =0.25*((kd!C$8+kd!D$8)*(kd!$A11+kd!$A12))*$C$3 -> 3 | E12: =0.25*((kd!D$8+kd!E$8)*(kd!$A11+kd!$A12))*$C$3 -> 3 | F12: =0.25*((kd!E$8+kd!F$8)*(kd!$A11+kd!$A12))*$C$3 -> 3 | G12: =0.25*((kd!F$8+kd!G$8)*(kd!$A11+kd!$A12))*$C$3 -> 3 | H12: =0.25*((kd!G$8+kd!H$8)*(kd!$A11+kd!$A12))*$C$3 -> 3 | I12: =0.25*((kd!H$8+kd!I$8)*(kd!$A11+kd!$A12))*$C$3 -> 3 | J12: =0.25*((kd!I$8+kd!J$8)*(kd!$A11+kd!$A12))*$C$3 -> 3 | K12: =0.25*((kd!J$8+kd!K$8)*(kd!$A11+kd!$A12))*$C$3 -> 3 | ... M12: =0.25*((kd!L$8+kd!M$8)*(kd!$A11+kd!$A12))*$C$3 -> 1.5
C13: 0 | D13: =0.25*((kd!C$8+kd!D$8)*(kd!$A12+kd!$A13))*$C$3 -> 3 | E13: =0.25*((kd!D$8+kd!E$8)*(kd!$A12+kd!$A13))*$C$3 -> 3 | F13: =0.25*((kd!E$8+kd!F$8)*(kd!$A12+kd!$A13))*$C$3 -> 3 | G13: =0.25*((kd!F$8+kd!G$8)*(kd!$A12+kd!$A13))*$C$3 -> 3 | H13: =0.25*((kd!G$8+kd!H$8)*(kd!$A12+kd!$A13))*$C$3 -> 3 | I13: =0.25*((kd!H$8+kd!I$8)*(kd!$A12+kd!$A13))*$C$3 -> 3 | J13: =0.25*((kd!I$8+kd!J$8)*(kd!$A12+kd!$A13))*$C$3 -> 3 | K13: =0.25*((kd!J$8+kd!K$8)*(kd!$A12+kd!$A13))*$C$3 -> 3 | ... M13: =0.25*((kd!L$8+kd!M$8)*(kd!$A12+kd!$A13))*$C$3 -> 1.5
C14: 0 | D14: =0.25*((kd!C$8+kd!D$8)*(kd!$A13+kd!$A14))*$C$3 -> 3 | E14: =0.25*((kd!D$8+kd!E$8)*(kd!$A13+kd!$A14))*$C$3 -> 3 | F14: =0.25*((kd!E$8+kd!F$8)*(kd!$A13+kd!$A14))*$C$3 -> 3 | G14: =0.25*((kd!F$8+kd!G$8)*(kd!$A13+kd!$A14))*$C$3 -> 3 | H14: =0.25*((kd!G$8+kd!H$8)*(kd!$A13+kd!$A14))*$C$3 -> 3 | I14: =0.25*((kd!H$8+kd!I$8)*(kd!$A13+kd!$A14))*$C$3 -> 3 | J14: =0.25*((kd!I$8+kd!J$8)*(kd!$A13+kd!$A14))*$C$3 -> 3 | K14: =0.25*((kd!J$8+kd!K$8)*(kd!$A13+kd!$A14))*$C$3 -> 3 | ... M14: =0.25*((kd!L$8+kd!M$8)*(kd!$A13+kd!$A14))*$C$3 -> 1.5
C15: 0 | D15: =0.25*((kd!C$8+kd!D$8)*(kd!$A14+kd!$A15))*$C$3 -> 3 | E15: =0.25*((kd!D$8+kd!E$8)*(kd!$A14+kd!$A15))*$C$3 -> 3 | F15: =0.25*((kd!E$8+kd!F$8)*(kd!$A14+kd!$A15))*$C$3 -> 3 | G15: =0.25*((kd!F$8+kd!G$8)*(kd!$A14+kd!$A15))*$C$3 -> 3 | H15: =0.25*((kd!G$8+kd!H$8)*(kd!$A14+kd!$A15))*$C$3 -> 3 | I15: =0.25*((kd!H$8+kd!I$8)*(kd!$A14+kd!$A15))*$C$3 -> 3 | J15: =0.25*((kd!I$8+kd!J$8)*(kd!$A14+kd!$A15))*$C$3 -> 3 | K15: =0.25*((kd!J$8+kd!K$8)*(kd!$A14+kd!$A15))*$C$3 -> 3 | ... M15: =0.25*((kd!L$8+kd!M$8)*(kd!$A14+kd!$A15))*$C$3 -> 1.5
C16: 0 | D16: =0.25*((kd!C$8+kd!D$8)*(kd!$A15+kd!$A16))*$C$3 -> 3 | E16: =0.25*((kd!D$8+kd!E$8)*(kd!$A15+kd!$A16))*$C$3 -> 3 | F16: =0.25*((kd!E$8+kd!F$8)*(kd!$A15+kd!$A16))*$C$3 -> 3 | G16: =0.25*((kd!F$8+kd!G$8)*(kd!$A15+kd!$A16))*$C$3 -> 3 | H16: =0.25*((kd!G$8+kd!H$8)*(kd!$A15+kd!$A16))*$C$3 -> 3 | I16: =0.25*((kd!H$8+kd!I$8)*(kd!$A15+kd!$A16))*$C$3 -> 3 | J16: =0.25*((kd!I$8+kd!J$8)*(kd!$A15+kd!$A16))*$C$3 -> 3 | K16: =0.25*((kd!J$8+kd!K$8)*(kd!$A15+kd!$A16))*$C$3 -> 3 | ... M16: =0.25*((kd!L$8+kd!M$8)*(kd!$A15+kd!$A16))*$C$3 -> 1.5
C17: 0 | D17: =0.25*((kd!C$8+kd!D$8)*(kd!$A16+kd!$A17))*$C$3 -> 3 | E17: =0.25*((kd!D$8+kd!E$8)*(kd!$A16+kd!$A17))*$C$3 -> 3 | F17: =0.25*((kd!E$8+kd!F$8)*(kd!$A16+kd!$A17))*$C$3 -> 3 | G17: =0.25*((kd!F$8+kd!G$8)*(kd!$A16+kd!$A17))*$C$3 -> 3 | H17: =0.25*((kd!G$8+kd!H$8)*(kd!$A16+kd!$A17))*$C$3 -> 3 | I17: =0.25*((kd!H$8+kd!I$8)*(kd!$A16+kd!$A17))*$C$3 -> 3 | J17: =0.25*((kd!I$8+kd!J$8)*(kd!$A16+kd!$A17))*$C$3 -> 3 | K17: =0.25*((kd!J$8+kd!K$8)*(kd!$A16+kd!$A17))*$C$3 -> 3 | ... M17: =0.25*((kd!L$8+kd!M$8)*(kd!$A16+kd!$A17))*$C$3 -> 1.5
C18: 0 | D18: =0.25*((kd!C$8+kd!D$8)*(kd!$A17+kd!$A18))*$C$3 -> 3 | E18: =0.25*((kd!D$8+kd!E$8)*(kd!$A17+kd!$A18))*$C$3 -> 3 | F18: =0.25*((kd!E$8+kd!F$8)*(kd!$A17+kd!$A18))*$C$3 -> 3 | G18: =0.25*((kd!F$8+kd!G$8)*(kd!$A17+kd!$A18))*$C$3 -> 3 | H18: =0.25*((kd!G$8+kd!H$8)*(kd!$A17+kd!$A18))*$C$3 -> 3 | I18: =0.25*((kd!H$8+kd!I$8)*(kd!$A17+kd!$A18))*$C$3 -> 3 | J18: =0.25*((kd!I$8+kd!J$8)*(kd!$A17+kd!$A18))*$C$3 -> 3 | K18: =0.25*((kd!J$8+kd!K$8)*(kd!$A17+kd!$A18))*$C$3 -> 3 | ... M18: =0.25*((kd!L$8+kd!M$8)*(kd!$A17+kd!$A18))*$C$3 -> 1.5
C19: 0 | D19: =0.25*((kd!C$8+kd!D$8)*(kd!$A18+kd!$A19))*$C$3 -> 3 | E19: =0.25*((kd!D$8+kd!E$8)*(kd!$A18+kd!$A19))*$C$3 -> 3 | F19: =0.25*((kd!E$8+kd!F$8)*(kd!$A18+kd!$A19))*$C$3 -> 3 | G19: =0.25*((kd!F$8+kd!G$8)*(kd!$A18+kd!$A19))*$C$3 -> 3 | H19: =0.25*((kd!G$8+kd!H$8)*(kd!$A18+kd!$A19))*$C$3 -> 3 | I19: =0.25*((kd!H$8+kd!I$8)*(kd!$A18+kd!$A19))*$C$3 -> 3 | J19: =0.25*((kd!I$8+kd!J$8)*(kd!$A18+kd!$A19))*$C$3 -> 3 | K19: =0.25*((kd!J$8+kd!K$8)*(kd!$A18+kd!$A19))*$C$3 -> 3 | ... M19: =0.25*((kd!L$8+kd!M$8)*(kd!$A18+kd!$A19))*$C$3 -> 1.5
C20: 0 | D20: =0.25*((kd!C$8+kd!D$8)*(kd!$A19+kd!$A20))*$C$3 -> 1.5 | E20: =0.25*((kd!D$8+kd!E$8)*(kd!$A19+kd!$A20))*$C$3 -> 1.5 | F20: =0.25*((kd!E$8+kd!F$8)*(kd!$A19+kd!$A20))*$C$3 -> 1.5 | G20: =0.25*((kd!F$8+kd!G$8)*(kd!$A19+kd!$A20))*$C$3 -> 1.5 | H20: =0.25*((kd!G$8+kd!H$8)*(kd!$A19+kd!$A20))*$C$3 -> 1.5 | I20: =0.25*((kd!H$8+kd!I$8)*(kd!$A19+kd!$A20))*$C$3 -> 1.5 | J20: =0.25*((kd!I$8+kd!J$8)*(kd!$A19+kd!$A20))*$C$3 -> 1.5 | K20: =0.25*((kd!J$8+kd!K$8)*(kd!$A19+kd!$A20))*$C$3 -> 1.5 | ... M20: =0.25*((kd!L$8+kd!M$8)*(kd!$A19+kd!$A20))*$C$3 -> 0.75

Sheet HorCap
A1: Horizontal Transport Capacity | D1: DY/DX*k
C7: element wise
C10: =(kd!$A10/kd!C$8)*kd!C10 -> 3 | D10: =(kd!$A10/kd!D$8)*kd!D10 -> 3 | E10: =(kd!$A10/kd!E$8)*kd!E10 -> 3 | F10: =(kd!$A10/kd!F$8)*kd!F10 -> 3 | G10: =(kd!$A10/kd!G$8)*kd!G10 -> 3 | H10: =(kd!$A10/kd!H$8)*kd!H10 -> 3 | I10: =(kd!$A10/kd!I$8)*kd!I10 -> 3 | J10: =(kd!$A10/kd!J$8)*kd!J10 -> 3 | ... L10: =(kd!$A10/kd!L$8)*kd!L10 -> 3
C11: =(kd!$A11/kd!C$8)*kd!C11 -> 3 | D11: =(kd!$A11/kd!D$8)*kd!D11 -> 3 | E11: =(kd!$A11/kd!E$8)*kd!E11 -> 3 | F11: =(kd!$A11/kd!F$8)*kd!F11 -> 3 | G11: =(kd!$A11/kd!G$8)*kd!G11 -> 3 | H11: =(kd!$A11/kd!H$8)*kd!H11 -> 3 | I11: =(kd!$A11/kd!I$8)*kd!I11 -> 3 | J11: =(kd!$A11/kd!J$8)*kd!J11 -> 3 | ... L11: =(kd!$A11/kd!L$8)*kd!L11 -> 3
C12: =(kd!$A12/kd!C$8)*kd!C12 -> 3 | D12: =(kd!$A12/kd!D$8)*kd!D12 -> 3 | E12: =(kd!$A12/kd!E$8)*kd!E12 -> 3 | F12: =(kd!$A12/kd!F$8)*kd!F12 -> 3 | G12: =(kd!$A12/kd!G$8)*kd!G12 -> 3 | H12: =(kd!$A12/kd!H$8)*kd!H12 -> 3 | I12: =(kd!$A12/kd!I$8)*kd!I12 -> 3 | J12: =(kd!$A12/kd!J$8)*kd!J12 -> 3 | ... L12: =(kd!$A12/kd!L$8)*kd!L12 -> 3
C13: =(kd!$A13/kd!C$8)*kd!C13 -> 3 | D13: =(kd!$A13/kd!D$8)*kd!D13 -> 3 | E13: =(kd!$A13/kd!E$8)*kd!E13 -> 3 | F13: =(kd!$A13/kd!F$8)*kd!F13 -> 3 | G13: =(kd!$A13/kd!G$8)*kd!G13 -> 3 | H13: =(kd!$A13/kd!H$8)*kd!H13 -> 3 | I13: =(kd!$A13/kd!I$8)*kd!I13 -> 3 | J13: =(kd!$A13/kd!J$8)*kd!J13 -> 3 | ... L13: =(kd!$A13/kd!L$8)*kd!L13 -> 3
C14: =(kd!$A14/kd!C$8)*kd!C14 -> 3 | D14: =(kd!$A14/kd!D$8)*kd!D14 -> 3 | E14: =(kd!$A14/kd!E$8)*kd!E14 -> 3 | F14: =(kd!$A14/kd!F$8)*kd!F14 -> 3 | G14: =(kd!$A14/kd!G$8)*kd!G14 -> 3 | H14: =(kd!$A14/kd!H$8)*kd!H14 -> 3 | I14: =(kd!$A14/kd!I$8)*kd!I14 -> 3 | J14: =(kd!$A14/kd!J$8)*kd!J14 -> 3 | ... L14: =(kd!$A14/kd!L$8)*kd!L14 -> 3
C15: =(kd!$A15/kd!C$8)*kd!C15 -> 3 | D15: =(kd!$A15/kd!D$8)*kd!D15 -> 3 | E15: =(kd!$A15/kd!E$8)*kd!E15 -> 3 | F15: =(kd!$A15/kd!F$8)*kd!F15 -> 3 | G15: =(kd!$A15/kd!G$8)*kd!G15 -> 3 | H15: =(kd!$A15/kd!H$8)*kd!H15 -> 3 | I15: =(kd!$A15/kd!I$8)*kd!I15 -> 3 | J15: =(kd!$A15/kd!J$8)*kd!J15 -> 3 | ... L15: =(kd!$A15/kd!L$8)*kd!L15 -> 3
C16: =(kd!$A16/kd!C$8)*kd!C16 -> 3 | D16: =(kd!$A16/kd!D$8)*kd!D16 -> 3 | E16: =(kd!$A16/kd!E$8)*kd!E16 -> 3 | F16: =(kd!$A16/kd!F$8)*kd!F16 -> 3 | G16: =(kd!$A16/kd!G$8)*kd!G16 -> 3 | H16: =(kd!$A16/kd!H$8)*kd!H16 -> 3 | I16: =(kd!$A16/kd!I$8)*kd!I16 -> 3 | J16: =(kd!$A16/kd!J$8)*kd!J16 -> 3 | ... L16: =(kd!$A16/kd!L$8)*kd!L16 -> 3
C17: =(kd!$A17/kd!C$8)*kd!C17 -> 3 | D17: =(kd!$A17/kd!D$8)*kd!D17 -> 3 | E17: =(kd!$A17/kd!E$8)*kd!E17 -> 3 | F17: =(kd!$A17/kd!F$8)*kd!F17 -> 3 | G17: =(kd!$A17/kd!G$8)*kd!G17 -> 3 | H17: =(kd!$A17/kd!H$8)*kd!H17 -> 3 | I17: =(kd!$A17/kd!I$8)*kd!I17 -> 3 | J17: =(kd!$A17/kd!J$8)*kd!J17 -> 3 | ... L17: =(kd!$A17/kd!L$8)*kd!L17 -> 3
C18: =(kd!$A18/kd!C$8)*kd!C18 -> 3 | D18: =(kd!$A18/kd!D$8)*kd!D18 -> 3 | E18: =(kd!$A18/kd!E$8)*kd!E18 -> 3 | F18: =(kd!$A18/kd!F$8)*kd!F18 -> 3 | G18: =(kd!$A18/kd!G$8)*kd!G18 -> 3 | H18: =(kd!$A18/kd!H$8)*kd!H18 -> 3 | I18: =(kd!$A18/kd!I$8)*kd!I18 -> 3 | J18: =(kd!$A18/kd!J$8)*kd!J18 -> 3 | ... L18: =(kd!$A18/kd!L$8)*kd!L18 -> 3
C19: =(kd!$A19/kd!C$8)*kd!C19 -> 3 | D19: =(kd!$A19/kd!D$8)*kd!D19 -> 3 | E19: =(kd!$A19/kd!E$8)*kd!E19 -> 3 | F19: =(kd!$A19/kd!F$8)*kd!F19 -> 3 | G19: =(kd!$A19/kd!G$8)*kd!G19 -> 3 | H19: =(kd!$A19/kd!H$8)*kd!H19 -> 3 | I19: =(kd!$A19/kd!I$8)*kd!I19 -> 3 | J19: =(kd!$A19/kd!J$8)*kd!J19 -> 3 | ... L19: =(kd!$A19/kd!L$8)*kd!L19 -> 3

Sheet VerCap
A1: Vertical transport capacity | D1: DX/DY*k
C7: element wise
C10: =(kd!C$8/kd!$A10)*kd!C10 -> 300 | D10: =(kd!D$8/kd!$A10)*kd!D10 -> 300 | E10: =(kd!E$8/kd!$A10)*kd!E10 -> 300 | F10: =(kd!F$8/kd!$A10)*kd!F10 -> 300 | G10: =(kd!G$8/kd!$A10)*kd!G10 -> 300 | H10: =(kd!H$8/kd!$A10)*kd!H10 -> 300 | I10: =(kd!I$8/kd!$A10)*kd!I10 -> 300 | J10: =(kd!J$8/kd!$A10)*kd!J10 -> 300 | ... L10: =(kd!L$8/kd!$A10)*kd!L10 -> 300
C11: =(kd!C$8/kd!$A11)*kd!C11 -> 300 | D11: =(kd!D$8/kd!$A11)*kd!D11 -> 300 | E11: =(kd!E$8/kd!$A11)*kd!E11 -> 300 | F11: =(kd!F$8/kd!$A11)*kd!F11 -> 300 | G11: =(kd!G$8/kd!$A11)*kd!G11 -> 300 | H11: =(kd!H$8/kd!$A11)*kd!H11 -> 300 | I11: =(kd!I$8/kd!$A11)*kd!I11 -> 300 | J11: =(kd!J$8/kd!$A11)*kd!J11 -> 300 | ... L11: =(kd!L$8/kd!$A11)*kd!L11 -> 300
C12: =(kd!C$8/kd!$A12)*kd!C12 -> 300 | D12: =(kd!D$8/kd!$A12)*kd!D12 -> 300 | E12: =(kd!E$8/kd!$A12)*kd!E12 -> 300 | F12: =(kd!F$8/kd!$A12)*kd!F12 -> 300 | G12: =(kd!G$8/kd!$A12)*kd!G12 -> 300 | H12: =(kd!H$8/kd!$A12)*kd!H12 -> 300 | I12: =(kd!I$8/kd!$A12)*kd!I12 -> 300 | J12: =(kd!J$8/kd!$A12)*kd!J12 -> 300 | ... L12: =(kd!L$8/kd!$A12)*kd!L12 -> 300
C13: =(kd!C$8/kd!$A13)*kd!C13 -> 300 | D13: =(kd!D$8/kd!$A13)*kd!D13 -> 300 | E13: =(kd!E$8/kd!$A13)*kd!E13 -> 300 | F13: =(kd!F$8/kd!$A13)*kd!F13 -> 300 | G13: =(kd!G$8/kd!$A13)*kd!G13 -> 300 | H13: =(kd!H$8/kd!$A13)*kd!H13 -> 300 | I13: =(kd!I$8/kd!$A13)*kd!I13 -> 300 | J13: =(kd!J$8/kd!$A13)*kd!J13 -> 300 | ... L13: =(kd!L$8/kd!$A13)*kd!L13 -> 300
C14: =(kd!C$8/kd!$A14)*kd!C14 -> 300 | D14: =(kd!D$8/kd!$A14)*kd!D14 -> 300 | E14: =(kd!E$8/kd!$A14)*kd!E14 -> 300 | F14: =(kd!F$8/kd!$A14)*kd!F14 -> 300 | G14: =(kd!G$8/kd!$A14)*kd!G14 -> 300 | H14: =(kd!H$8/kd!$A14)*kd!H14 -> 300 | I14: =(kd!I$8/kd!$A14)*kd!I14 -> 300 | J14: =(kd!J$8/kd!$A14)*kd!J14 -> 300 | ... L14: =(kd!L$8/kd!$A14)*kd!L14 -> 300
C15: =(kd!C$8/kd!$A15)*kd!C15 -> 300 | D15: =(kd!D$8/kd!$A15)*kd!D15 -> 300 | E15: =(kd!E$8/kd!$A15)*kd!E15 -> 300 | F15: =(kd!F$8/kd!$A15)*kd!F15 -> 300 | G15: =(kd!G$8/kd!$A15)*kd!G15 -> 300 | H15: =(kd!H$8/kd!$A15)*kd!H15 -> 300 | I15: =(kd!I$8/kd!$A15)*kd!I15 -> 300 | J15: =(kd!J$8/kd!$A15)*kd!J15 -> 300 | ... L15: =(kd!L$8/kd!$A15)*kd!L15 -> 300
C16: =(kd!C$8/kd!$A16)*kd!C16 -> 300 | D16: =(kd!D$8/kd!$A16)*kd!D16 -> 300 | E16: =(kd!E$8/kd!$A16)*kd!E16 -> 300 | F16: =(kd!F$8/kd!$A16)*kd!F16 -> 300 | G16: =(kd!G$8/kd!$A16)*kd!G16 -> 300 | H16: =(kd!H$8/kd!$A16)*kd!H16 -> 300 | I16: =(kd!I$8/kd!$A16)*kd!I16 -> 300 | J16: =(kd!J$8/kd!$A16)*kd!J16 -> 300 | ... L16: =(kd!L$8/kd!$A16)*kd!L16 -> 300
C17: =(kd!C$8/kd!$A17)*kd!C17 -> 300 | D17: =(kd!D$8/kd!$A17)*kd!D17 -> 300 | E17: =(kd!E$8/kd!$A17)*kd!E17 -> 300 | F17: =(kd!F$8/kd!$A17)*kd!F17 -> 300 | G17: =(kd!G$8/kd!$A17)*kd!G17 -> 300 | H17: =(kd!H$8/kd!$A17)*kd!H17 -> 300 | I17: =(kd!I$8/kd!$A17)*kd!I17 -> 300 | J17: =(kd!J$8/kd!$A17)*kd!J17 -> 300 | ... L17: =(kd!L$8/kd!$A17)*kd!L17 -> 300
C18: =(kd!C$8/kd!$A18)*kd!C18 -> 300 | D18: =(kd!D$8/kd!$A18)*kd!D18 -> 300 | E18: =(kd!E$8/kd!$A18)*kd!E18 -> 300 | F18: =(kd!F$8/kd!$A18)*kd!F18 -> 300 | G18: =(kd!G$8/kd!$A18)*kd!G18 -> 300 | H18: =(kd!H$8/kd!$A18)*kd!H18 -> 300 | I18: =(kd!I$8/kd!$A18)*kd!I18 -> 300 | J18: =(kd!J$8/kd!$A18)*kd!J18 -> 300 | ... L18: =(kd!L$8/kd!$A18)*kd!L18 -> 300
C19: =(kd!C$8/kd!$A19)*kd!C19 -> 300 | D19: =(kd!D$8/kd!$A19)*kd!D19 -> 300 | E19: =(kd!E$8/kd!$A19)*kd!E19 -> 300 | F19: =(kd!F$8/kd!$A19)*kd!F19 -> 300 | G19: =(kd!G$8/kd!$A19)*kd!G19 -> 300 | H19: =(kd!H$8/kd!$A19)*kd!H19 -> 300 | I19: =(kd!I$8/kd!$A19)*kd!I19 -> 300 | J19: =(kd!J$8/kd!$A19)*kd!J19 -> 300 | ... L19: =(kd!L$8/kd!$A19)*kd!L19 -> 300

Sheet north
A1: North coefficient
C10: =(VerCap!B9+VerCap!C9)/2 -> 0 | D10: =(VerCap!C9+VerCap!D9)/2 -> 0 | E10: =(VerCap!D9+VerCap!E9)/2 -> 0 | F10: =(VerCap!E9+VerCap!F9)/2 -> 0 | G10: =(VerCap!F9+VerCap!G9)/2 -> 0 | H10: =(VerCap!G9+VerCap!H9)/2 -> 0 | I10: =(VerCap!H9+VerCap!I9)/2 -> 0 | J10: =(VerCap!I9+VerCap!J9)/2 -> 0 | ... M10: =(VerCap!L9+VerCap!M9)/2 -> 0
C11: =(VerCap!B10+VerCap!C10)/2 -> 150 | D11: =(VerCap!C10+VerCap!D10)/2 -> 300 | E11: =(VerCap!D10+VerCap!E10)/2 -> 300 | F11: =(VerCap!E10+VerCap!F10)/2 -> 300 | G11: =(VerCap!F10+VerCap!G10)/2 -> 300 | H11: =(VerCap!G10+VerCap!H10)/2 -> 300 | I11: =(VerCap!H10+VerCap!I10)/2 -> 300 | J11: =(VerCap!I10+VerCap!J10)/2 -> 300 | ... M11: =(VerCap!L10+VerCap!M10)/2 -> 150
C12: =(VerCap!B11+VerCap!C11)/2 -> 150 | D12: =(VerCap!C11+VerCap!D11)/2 -> 300 | E12: =(VerCap!D11+VerCap!E11)/2 -> 300 | F12: =(VerCap!E11+VerCap!F11)/2 -> 300 | G12: =(VerCap!F11+VerCap!G11)/2 -> 300 | H12: =(VerCap!G11+VerCap!H11)/2 -> 300 | I12: =(VerCap!H11+VerCap!I11)/2 -> 300 | J12: =(VerCap!I11+VerCap!J11)/2 -> 300 | ... M12: =(VerCap!L11+VerCap!M11)/2 -> 150
C13: =(VerCap!B12+VerCap!C12)/2 -> 150 | D13: =(VerCap!C12+VerCap!D12)/2 -> 300 | E13: =(VerCap!D12+VerCap!E12)/2 -> 300 | F13: =(VerCap!E12+VerCap!F12)/2 -> 300 | G13: =(VerCap!F12+VerCap!G12)/2 -> 300 | H13: =(VerCap!G12+VerCap!H12)/2 -> 300 | I13: =(VerCap!H12+VerCap!I12)/2 -> 300 | J13: =(VerCap!I12+VerCap!J12)/2 -> 300 | ... M13: =(VerCap!L12+VerCap!M12)/2 -> 150
C14: =(VerCap!B13+VerCap!C13)/2 -> 150 | D14: =(VerCap!C13+VerCap!D13)/2 -> 300 | E14: =(VerCap!D13+VerCap!E13)/2 -> 300 | F14: =(VerCap!E13+VerCap!F13)/2 -> 300 | G14: =(VerCap!F13+VerCap!G13)/2 -> 300 | H14: =(VerCap!G13+VerCap!H13)/2 -> 300 | I14: =(VerCap!H13+VerCap!I13)/2 -> 300 | J14: =(VerCap!I13+VerCap!J13)/2 -> 300 | ... M14: =(VerCap!L13+VerCap!M13)/2 -> 150
C15: =(VerCap!B14+VerCap!C14)/2 -> 150 | D15: =(VerCap!C14+VerCap!D14)/2 -> 300 | E15: =(VerCap!D14+VerCap!E14)/2 -> 300 | F15: =(VerCap!E14+VerCap!F14)/2 -> 300 | G15: =(VerCap!F14+VerCap!G14)/2 -> 300 | H15: =(VerCap!G14+VerCap!H14)/2 -> 300 | I15: =(VerCap!H14+VerCap!I14)/2 -> 300 | J15: =(VerCap!I14+VerCap!J14)/2 -> 300 | ... M15: =(VerCap!L14+VerCap!M14)/2 -> 150
C16: =(VerCap!B15+VerCap!C15)/2 -> 150 | D16: =(VerCap!C15+VerCap!D15)/2 -> 300 | E16: =(VerCap!D15+VerCap!E15)/2 -> 300 | F16: =(VerCap!E15+VerCap!F15)/2 -> 300 | G16: =(VerCap!F15+VerCap!G15)/2 -> 300 | H16: =(VerCap!G15+VerCap!H15)/2 -> 300 | I16: =(VerCap!H15+VerCap!I15)/2 -> 300 | J16: =(VerCap!I15+VerCap!J15)/2 -> 300 | ... M16: =(VerCap!L15+VerCap!M15)/2 -> 150
C17: =(VerCap!B16+VerCap!C16)/2 -> 150 | D17: =(VerCap!C16+VerCap!D16)/2 -> 300 | E17: =(VerCap!D16+VerCap!E16)/2 -> 300 | F17: =(VerCap!E16+VerCap!F16)/2 -> 300 | G17: =(VerCap!F16+VerCap!G16)/2 -> 300 | H17: =(VerCap!G16+VerCap!H16)/2 -> 300 | I17: =(VerCap!H16+VerCap!I16)/2 -> 300 | J17: =(VerCap!I16+VerCap!J16)/2 -> 300 | ... M17: =(VerCap!L16+VerCap!M16)/2 -> 150
C18: =(VerCap!B17+VerCap!C17)/2 -> 150 | D18: =(VerCap!C17+VerCap!D17)/2 -> 300 | E18: =(VerCap!D17+VerCap!E17)/2 -> 300 | F18: =(VerCap!E17+VerCap!F17)/2 -> 300 | G18: =(VerCap!F17+VerCap!G17)/2 -> 300 | H18: =(VerCap!G17+VerCap!H17)/2 -> 300 | I18: =(VerCap!H17+VerCap!I17)/2 -> 300 | J18: =(VerCap!I17+VerCap!J17)/2 -> 300 | ... M18: =(VerCap!L17+VerCap!M17)/2 -> 150
C19: =(VerCap!B18+VerCap!C18)/2 -> 150 | D19: =(VerCap!C18+VerCap!D18)/2 -> 300 | E19: =(VerCap!D18+VerCap!E18)/2 -> 300 | F19: =(VerCap!E18+VerCap!F18)/2 -> 300 | G19: =(VerCap!F18+VerCap!G18)/2 -> 300 | H19: =(VerCap!G18+VerCap!H18)/2 -> 300 | I19: =(VerCap!H18+VerCap!I18)/2 -> 300 | J19: =(VerCap!I18+VerCap!J18)/2 -> 300 | ... M19: =(VerCap!L18+VerCap!M18)/2 -> 150
C20: =(VerCap!B19+VerCap!C19)/2 -> 150 | D20: =(VerCap!C19+VerCap!D19)/2 -> 300 | E20: =(VerCap!D19+VerCap!E19)/2 -> 300 | F20: =(VerCap!E19+VerCap!F19)/2 -> 300 | G20: =(VerCap!F19+VerCap!G19)/2 -> 300 | H20: =(VerCap!G19+VerCap!H19)/2 -> 300 | I20: =(VerCap!H19+VerCap!I19)/2 -> 300 | J20: =(VerCap!I19+VerCap!J19)/2 -> 300 | ... M20: =(VerCap!L19+VerCap!M19)/2 -> 150

Sheet east
A1: East Coefficient
C10: =(HorCap!C10+HorCap!C9)/2 -> 1.5 | D10: =(HorCap!D10+HorCap!D9)/2 -> 1.5 | E10: =(HorCap!E10+HorCap!E9)/2 -> 1.5 | F10: =(HorCap!F10+HorCap!F9)/2 -> 1.5 | G10: =(HorCap!G10+HorCap!G9)/2 -> 1.5 | H10: =(HorCap!H10+HorCap!H9)/2 -> 1.5 | I10: =(HorCap!I10+HorCap!I9)/2 -> 1.5 | J10: =(HorCap!J10+HorCap!J9)/2 -> 1.5 | ... M10: =(HorCap!M10+HorCap!M9)/2 -> 0
C11: =(HorCap!C11+HorCap!C10)/2 -> 3 | D11: =(HorCap!D11+HorCap!D10)/2 -> 3 | E11: =(HorCap!E11+HorCap!E10)/2 -> 3 | F11: =(HorCap!F11+HorCap!F10)/2 -> 3 | G11: =(HorCap!G11+HorCap!G10)/2 -> 3 | H11: =(HorCap!H11+HorCap!H10)/2 -> 3 | I11: =(HorCap!I11+HorCap!I10)/2 -> 3 | J11: =(HorCap!J11+HorCap!J10)/2 -> 3 | ... M11: =(HorCap!M11+HorCap!M10)/2 -> 0
C12: =(HorCap!C12+HorCap!C11)/2 -> 3 | D12: =(HorCap!D12+HorCap!D11)/2 -> 3 | E12: =(HorCap!E12+HorCap!E11)/2 -> 3 | F12: =(HorCap!F12+HorCap!F11)/2 -> 3 | G12: =(HorCap!G12+HorCap!G11)/2 -> 3 | H12: =(HorCap!H12+HorCap!H11)/2 -> 3 | I12: =(HorCap!I12+HorCap!I11)/2 -> 3 | J12: =(HorCap!J12+HorCap!J11)/2 -> 3 | ... M12: =(HorCap!M12+HorCap!M11)/2 -> 0
C13: =(HorCap!C13+HorCap!C12)/2 -> 3 | D13: =(HorCap!D13+HorCap!D12)/2 -> 3 | E13: =(HorCap!E13+HorCap!E12)/2 -> 3 | F13: =(HorCap!F13+HorCap!F12)/2 -> 3 | G13: =(HorCap!G13+HorCap!G12)/2 -> 3 | H13: =(HorCap!H13+HorCap!H12)/2 -> 3 | I13: =(HorCap!I13+HorCap!I12)/2 -> 3 | J13: =(HorCap!J13+HorCap!J12)/2 -> 3 | ... M13: =(HorCap!M13+HorCap!M12)/2 -> 0
C14: =(HorCap!C14+HorCap!C13)/2 -> 3 | D14: =(HorCap!D14+HorCap!D13)/2 -> 3 | E14: =(HorCap!E14+HorCap!E13)/2 -> 3 | F14: =(HorCap!F14+HorCap!F13)/2 -> 3 | G14: =(HorCap!G14+HorCap!G13)/2 -> 3 | H14: =(HorCap!H14+HorCap!H13)/2 -> 3 | I14: =(HorCap!I14+HorCap!I13)/2 -> 3 | J14: =(HorCap!J14+HorCap!J13)/2 -> 3 | ... M14: =(HorCap!M14+HorCap!M13)/2 -> 0
C15: =(HorCap!C15+HorCap!C14)/2 -> 3 | D15: =(HorCap!D15+HorCap!D14)/2 -> 3 | E15: =(HorCap!E15+HorCap!E14)/2 -> 3 | F15: =(HorCap!F15+HorCap!F14)/2 -> 3 | G15: =(HorCap!G15+HorCap!G14)/2 -> 3 | H15: =(HorCap!H15+HorCap!H14)/2 -> 3 | I15: =(HorCap!I15+HorCap!I14)/2 -> 3 | J15: =(HorCap!J15+HorCap!J14)/2 -> 3 | ... M15: =(HorCap!M15+HorCap!M14)/2 -> 0
C16: =(HorCap!C16+HorCap!C15)/2 -> 3 | D16: =(HorCap!D16+HorCap!D15)/2 -> 3 | E16: =(HorCap!E16+HorCap!E15)/2 -> 3 | F16: =(HorCap!F16+HorCap!F15)/2 -> 3 | G16: =(HorCap!G16+HorCap!G15)/2 -> 3 | H16: =(HorCap!H16+HorCap!H15)/2 -> 3 | I16: =(HorCap!I16+HorCap!I15)/2 -> 3 | J16: =(HorCap!J16+HorCap!J15)/2 -> 3 | ... M16: =(HorCap!M16+HorCap!M15)/2 -> 0
C17: =(HorCap!C17+HorCap!C16)/2 -> 3 | D17: =(HorCap!D17+HorCap!D16)/2 -> 3 | E17: =(HorCap!E17+HorCap!E16)/2 -> 3 | F17: =(HorCap!F17+HorCap!F16)/2 -> 3 | G17: =(HorCap!G17+HorCap!G16)/2 -> 3 | H17: =(HorCap!H17+HorCap!H16)/2 -> 3 | I17: =(HorCap!I17+HorCap!I16)/2 -> 3 | J17: =(HorCap!J17+HorCap!J16)/2 -> 3 | ... M17: =(HorCap!M17+HorCap!M16)/2 -> 0
C18: =(HorCap!C18+HorCap!C17)/2 -> 3 | D18: =(HorCap!D18+HorCap!D17)/2 -> 3 | E18: =(HorCap!E18+HorCap!E17)/2 -> 3 | F18: =(HorCap!F18+HorCap!F17)/2 -> 3 | G18: =(HorCap!G18+HorCap!G17)/2 -> 3 | H18: =(HorCap!H18+HorCap!H17)/2 -> 3 | I18: =(HorCap!I18+HorCap!I17)/2 -> 3 | J18: =(HorCap!J18+HorCap!J17)/2 -> 3 | ... M18: =(HorCap!M18+HorCap!M17)/2 -> 0
C19: =(HorCap!C19+HorCap!C18)/2 -> 3 | D19: =(HorCap!D19+HorCap!D18)/2 -> 3 | E19: =(HorCap!E19+HorCap!E18)/2 -> 3 | F19: =(HorCap!F19+HorCap!F18)/2 -> 3 | G19: =(HorCap!G19+HorCap!G18)/2 -> 3 | H19: =(HorCap!H19+HorCap!H18)/2 -> 3 | I19: =(HorCap!I19+HorCap!I18)/2 -> 3 | J19: =(HorCap!J19+HorCap!J18)/2 -> 3 | ... M19: =(HorCap!M19+HorCap!M18)/2 -> 0
C20: =(HorCap!C20+HorCap!C19)/2 -> 1.5 | D20: =(HorCap!D20+HorCap!D19)/2 -> 1.5 | E20: =(HorCap!E20+HorCap!E19)/2 -> 1.5 | F20: =(HorCap!F20+HorCap!F19)/2 -> 1.5 | G20: =(HorCap!G20+HorCap!G19)/2 -> 1.5 | H20: =(HorCap!H20+HorCap!H19)/2 -> 1.5 | I20: =(HorCap!I20+HorCap!I19)/2 -> 1.5 | J20: =(HorCap!J20+HorCap!J19)/2 -> 1.5 | ... M20: =(HorCap!M20+HorCap!M19)/2 -> 0

Sheet south
A1: South coefficient
C10: =(VerCap!C10+VerCap!B10)/2 -> 150 | D10: =(VerCap!D10+VerCap!C10)/2 -> 300 | E10: =(VerCap!E10+VerCap!D10)/2 -> 300 | F10: =(VerCap!F10+VerCap!E10)/2 -> 300 | G10: =(VerCap!G10+VerCap!F10)/2 -> 300 | H10: =(VerCap!H10+VerCap!G10)/2 -> 300 | I10: =(VerCap!I10+VerCap!H10)/2 -> 300 | J10: =(VerCap!J10+VerCap!I10)/2 -> 300 | ... M10: =(VerCap!M10+VerCap!L10)/2 -> 150
C11: =(VerCap!C11+VerCap!B11)/2 -> 150 | D11: =(VerCap!D11+VerCap!C11)/2 -> 300 | E11: =(VerCap!E11+VerCap!D11)/2 -> 300 | F11: =(VerCap!F11+VerCap!E11)/2 -> 300 | G11: =(VerCap!G11+VerCap!F11)/2 -> 300 | H11: =(VerCap!H11+VerCap!G11)/2 -> 300 | I11: =(VerCap!I11+VerCap!H11)/2 -> 300 | J11: =(VerCap!J11+VerCap!I11)/2 -> 300 | ... M11: =(VerCap!M11+VerCap!L11)/2 -> 150
C12: =(VerCap!C12+VerCap!B12)/2 -> 150 | D12: =(VerCap!D12+VerCap!C12)/2 -> 300 | E12: =(VerCap!E12+VerCap!D12)/2 -> 300 | F12: =(VerCap!F12+VerCap!E12)/2 -> 300 | G12: =(VerCap!G12+VerCap!F12)/2 -> 300 | H12: =(VerCap!H12+VerCap!G12)/2 -> 300 | I12: =(VerCap!I12+VerCap!H12)/2 -> 300 | J12: =(VerCap!J12+VerCap!I12)/2 -> 300 | ... M12: =(VerCap!M12+VerCap!L12)/2 -> 150
C13: =(VerCap!C13+VerCap!B13)/2 -> 150 | D13: =(VerCap!D13+VerCap!C13)/2 -> 300 | E13: =(VerCap!E13+VerCap!D13)/2 -> 300 | F13: =(VerCap!F13+VerCap!E13)/2 -> 300 | G13: =(VerCap!G13+VerCap!F13)/2 -> 300 | H13: =(VerCap!H13+VerCap!G13)/2 -> 300 | I13: =(VerCap!I13+VerCap!H13)/2 -> 300 | J13: =(VerCap!J13+VerCap!I13)/2 -> 300 | ... M13: =(VerCap!M13+VerCap!L13)/2 -> 150
C14: =(VerCap!C14+VerCap!B14)/2 -> 150 | D14: =(VerCap!D14+VerCap!C14)/2 -> 300 | E14: =(VerCap!E14+VerCap!D14)/2 -> 300 | F14: =(VerCap!F14+VerCap!E14)/2 -> 300 | G14: =(VerCap!G14+VerCap!F14)/2 -> 300 | H14: =(VerCap!H14+VerCap!G14)/2 -> 300 | I14: =(VerCap!I14+VerCap!H14)/2 -> 300 | J14: =(VerCap!J14+VerCap!I14)/2 -> 300 | ... M14: =(VerCap!M14+VerCap!L14)/2 -> 150
C15: =(VerCap!C15+VerCap!B15)/2 -> 150 | D15: =(VerCap!D15+VerCap!C15)/2 -> 300 | E15: =(VerCap!E15+VerCap!D15)/2 -> 300 | F15: =(VerCap!F15+VerCap!E15)/2 -> 300 | G15: =(VerCap!G15+VerCap!F15)/2 -> 300 | H15: =(VerCap!H15+VerCap!G15)/2 -> 300 | I15: =(VerCap!I15+VerCap!H15)/2 -> 300 | J15: =(VerCap!J15+VerCap!I15)/2 -> 300 | ... M15: =(VerCap!M15+VerCap!L15)/2 -> 150
C16: =(VerCap!C16+VerCap!B16)/2 -> 150 | D16: =(VerCap!D16+VerCap!C16)/2 -> 300 | E16: =(VerCap!E16+VerCap!D16)/2 -> 300 | F16: =(VerCap!F16+VerCap!E16)/2 -> 300 | G16: =(VerCap!G16+VerCap!F16)/2 -> 300 | H16: =(VerCap!H16+VerCap!G16)/2 -> 300 | I16: =(VerCap!I16+VerCap!H16)/2 -> 300 | J16: =(VerCap!J16+VerCap!I16)/2 -> 300 | ... M16: =(VerCap!M16+VerCap!L16)/2 -> 150
C17: =(VerCap!C17+VerCap!B17)/2 -> 150 | D17: =(VerCap!D17+VerCap!C17)/2 -> 300 | E17: =(VerCap!E17+VerCap!D17)/2 -> 300 | F17: =(VerCap!F17+VerCap!E17)/2 -> 300 | G17: =(VerCap!G17+VerCap!F17)/2 -> 300 | H17: =(VerCap!H17+VerCap!G17)/2 -> 300 | I17: =(VerCap!I17+VerCap!H17)/2 -> 300 | J17: =(VerCap!J17+VerCap!I17)/2 -> 300 | ... M17: =(VerCap!M17+VerCap!L17)/2 -> 150
C18: =(VerCap!C18+VerCap!B18)/2 -> 150 | D18: =(VerCap!D18+VerCap!C18)/2 -> 300 | E18: =(VerCap!E18+VerCap!D18)/2 -> 300 | F18: =(VerCap!F18+VerCap!E18)/2 -> 300 | G18: =(VerCap!G18+VerCap!F18)/2 -> 300 | H18: =(VerCap!H18+VerCap!G18)/2 -> 300 | I18: =(VerCap!I18+VerCap!H18)/2 -> 300 | J18: =(VerCap!J18+VerCap!I18)/2 -> 300 | ... M18: =(VerCap!M18+VerCap!L18)/2 -> 150
C19: =(VerCap!C19+VerCap!B19)/2 -> 150 | D19: =(VerCap!D19+VerCap!C19)/2 -> 300 | E19: =(VerCap!E19+VerCap!D19)/2 -> 300 | F19: =(VerCap!F19+VerCap!E19)/2 -> 300 | G19: =(VerCap!G19+VerCap!F19)/2 -> 300 | H19: =(VerCap!H19+VerCap!G19)/2 -> 300 | I19: =(VerCap!I19+VerCap!H19)/2 -> 300 | J19: =(VerCap!J19+VerCap!I19)/2 -> 300 | ... M19: =(VerCap!M19+VerCap!L19)/2 -> 150
C20: =(VerCap!C20+VerCap!B20)/2 -> 0 | D20: =(VerCap!D20+VerCap!C20)/2 -> 0 | E20: =(VerCap!E20+VerCap!D20)/2 -> 0 | F20: =(VerCap!F20+VerCap!E20)/2 -> 0 | G20: =(VerCap!G20+VerCap!F20)/2 -> 0 | H20: =(VerCap!H20+VerCap!G20)/2 -> 0 | I20: =(VerCap!I20+VerCap!H20)/2 -> 0 | J20: =(VerCap!J20+VerCap!I20)/2 -> 0 | ... M20: =(VerCap!M20+VerCap!L20)/2 -> 0

Sheet west
A1: West coefficient
C10: =(HorCap!B9+HorCap!B10)/2 -> 0 | D10: =(HorCap!C9+HorCap!C10)/2 -> 1.5 | E10: =(HorCap!D9+HorCap!D10)/2 -> 1.5 | F10: =(HorCap!E9+HorCap!E10)/2 -> 1.5 | G10: =(HorCap!F9+HorCap!F10)/2 -> 1.5 | H10: =(HorCap!G9+HorCap!G10)/2 -> 1.5 | I10: =(HorCap!H9+HorCap!H10)/2 -> 1.5 | J10: =(HorCap!I9+HorCap!I10)/2 -> 1.5 | ... M10: =(HorCap!L9+HorCap!L10)/2 -> 1.5
C11: =(HorCap!B10+HorCap!B11)/2 -> 0 | D11: =(HorCap!C10+HorCap!C11)/2 -> 3 | E11: =(HorCap!D10+HorCap!D11)/2 -> 3 | F11: =(HorCap!E10+HorCap!E11)/2 -> 3 | G11: =(HorCap!F10+HorCap!F11)/2 -> 3 | H11: =(HorCap!G10+HorCap!G11)/2 -> 3 | I11: =(HorCap!H10+HorCap!H11)/2 -> 3 | J11: =(HorCap!I10+HorCap!I11)/2 -> 3 | ... M11: =(HorCap!L10+HorCap!L11)/2 -> 3
C12: =(HorCap!B11+HorCap!B12)/2 -> 0 | D12: =(HorCap!C11+HorCap!C12)/2 -> 3 | E12: =(HorCap!D11+HorCap!D12)/2 -> 3 | F12: =(HorCap!E11+HorCap!E12)/2 -> 3 | G12: =(HorCap!F11+HorCap!F12)/2 -> 3 | H12: =(HorCap!G11+HorCap!G12)/2 -> 3 | I12: =(HorCap!H11+HorCap!H12)/2 -> 3 | J12: =(HorCap!I11+HorCap!I12)/2 -> 3 | ... M12: =(HorCap!L11+HorCap!L12)/2 -> 3
C13: =(HorCap!B12+HorCap!B13)/2 -> 0 | D13: =(HorCap!C12+HorCap!C13)/2 -> 3 | E13: =(HorCap!D12+HorCap!D13)/2 -> 3 | F13: =(HorCap!E12+HorCap!E13)/2 -> 3 | G13: =(HorCap!F12+HorCap!F13)/2 -> 3 | H13: =(HorCap!G12+HorCap!G13)/2 -> 3 | I13: =(HorCap!H12+HorCap!H13)/2 -> 3 | J13: =(HorCap!I12+HorCap!I13)/2 -> 3 | ... M13: =(HorCap!L12+HorCap!L13)/2 -> 3
C14: =(HorCap!B13+HorCap!B14)/2 -> 0 | D14: =(HorCap!C13+HorCap!C14)/2 -> 3 | E14: =(HorCap!D13+HorCap!D14)/2 -> 3 | F14: =(HorCap!E13+HorCap!E14)/2 -> 3 | G14: =(HorCap!F13+HorCap!F14)/2 -> 3 | H14: =(HorCap!G13+HorCap!G14)/2 -> 3 | I14: =(HorCap!H13+HorCap!H14)/2 -> 3 | J14: =(HorCap!I13+HorCap!I14)/2 -> 3 | ... M14: =(HorCap!L13+HorCap!L14)/2 -> 3
C15: =(HorCap!B14+HorCap!B15)/2 -> 0 | D15: =(HorCap!C14+HorCap!C15)/2 -> 3 | E15: =(HorCap!D14+HorCap!D15)/2 -> 3 | F15: =(HorCap!E14+HorCap!E15)/2 -> 3 | G15: =(HorCap!F14+HorCap!F15)/2 -> 3 | H15: =(HorCap!G14+HorCap!G15)/2 -> 3 | I15: =(HorCap!H14+HorCap!H15)/2 -> 3 | J15: =(HorCap!I14+HorCap!I15)/2 -> 3 | ... M15: =(HorCap!L14+HorCap!L15)/2 -> 3
C16: =(HorCap!B15+HorCap!B16)/2 -> 0 | D16: =(HorCap!C15+HorCap!C16)/2 -> 3 | E16: =(HorCap!D15+HorCap!D16)/2 -> 3 | F16: =(HorCap!E15+HorCap!E16)/2 -> 3 | G16: =(HorCap!F15+HorCap!F16)/2 -> 3 | H16: =(HorCap!G15+HorCap!G16)/2 -> 3 | I16: =(HorCap!H15+HorCap!H16)/2 -> 3 | J16: =(HorCap!I15+HorCap!I16)/2 -> 3 | ... M16: =(HorCap!L15+HorCap!L16)/2 -> 3
C17: =(HorCap!B16+HorCap!B17)/2 -> 0 | D17: =(HorCap!C16+HorCap!C17)/2 -> 3 | E17: =(HorCap!D16+HorCap!D17)/2 -> 3 | F17: =(HorCap!E16+HorCap!E17)/2 -> 3 | G17: =(HorCap!F16+HorCap!F17)/2 -> 3 | H17: =(HorCap!G16+HorCap!G17)/2 -> 3 | I17: =(HorCap!H16+HorCap!H17)/2 -> 3 | J17: =(HorCap!I16+HorCap!I17)/2 -> 3 | ... M17: =(HorCap!L16+HorCap!L17)/2 -> 3
C18: =(HorCap!B17+HorCap!B18)/2 -> 0 | D18: =(HorCap!C17+HorCap!C18)/2 -> 3 | E18: =(HorCap!D17+HorCap!D18)/2 -> 3 | F18: =(HorCap!E17+HorCap!E18)/2 -> 3 | G18: =(HorCap!F17+HorCap!F18)/2 -> 3 | H18: =(HorCap!G17+HorCap!G18)/2 -> 3 | I18: =(HorCap!H17+HorCap!H18)/2 -> 3 | J18: =(HorCap!I17+HorCap!I18)/2 -> 3 | ... M18: =(HorCap!L17+HorCap!L18)/2 -> 3
C19: =(HorCap!B18+HorCap!B19)/2 -> 0 | D19: =(HorCap!C18+HorCap!C19)/2 -> 3 | E19: =(HorCap!D18+HorCap!D19)/2 -> 3 | F19: =(HorCap!E18+HorCap!E19)/2 -> 3 | G19: =(HorCap!F18+HorCap!F19)/2 -> 3 | H19: =(HorCap!G18+HorCap!G19)/2 -> 3 | I19: =(HorCap!H18+HorCap!H19)/2 -> 3 | J19: =(HorCap!I18+HorCap!I19)/2 -> 3 | ... M19: =(HorCap!L18+HorCap!L19)/2 -> 3
C20: =(HorCap!B19+HorCap!B20)/2 -> 0 | D20: =(HorCap!C19+HorCap!C20)/2 -> 1.5 | E20: =(HorCap!D19+HorCap!D20)/2 -> 1.5 | F20: =(HorCap!E19+HorCap!E20)/2 -> 1.5 | G20: =(HorCap!F19+HorCap!F20)/2 -> 1.5 | H20: =(HorCap!G19+HorCap!G20)/2 -> 1.5 | I20: =(HorCap!H19+HorCap!H20)/2 -> 1.5 | J20: =(HorCap!I19+HorCap!I20)/2 -> 1.5 | ... M20: =(HorCap!L19+HorCap!L20)/2 -> 1.5

Sheet Qwest
B2: Flux from the west
C10: =west!C10*(H!B10-H!C10) -> 0 | D10: =west!D10*(H!C10-H!D10) -> -0.26275581 | E10: =west!E10*(H!D10-H!E10) -> -0.38859766 | F10: =west!F10*(H!E10-H!F10) -> -0.43529875 | G10: =west!G10*(H!F10-H!G10) -> -0.44646308 | H10: =west!H10*(H!G10-H!H10) -> -0.44895043 | I10: =west!I10*(H!H10-H!I10) -> -0.44914537 | J10: =west!J10*(H!I10-H!J10) -> -0.44755011 | ... M10: =west!M10*(H!L10-H!M10) -> -0.26639238
C11: =west!C11*(H!B11-H!C11) -> 0 | D11: =west!D11*(H!C11-H!D11) -> -0.50925325 | E11: =west!E11*(H!D11-H!E11) -> -0.77798677 | F11: =west!F11*(H!E11-H!F11) -> -0.87095287 | G11: =west!G11*(H!F11-H!G11) -> -0.89301292 | H11: =west!H11*(H!G11-H!H11) -> -0.8979238 | I11: =west!I11*(H!H11-H!I11) -> -0.89830869 | J11: =west!J11*(H!I11-H!J11) -> -0.89515926 | ... M11: =west!M11*(H!L11-H!M11) -> -0.53670449
C12: =west!C12*(H!B12-H!C12) -> 0 | D12: =west!D12*(H!C12-H!D12) -> -0.46030754 | E12: =west!E12*(H!D12-H!E12) -> -0.78053583 | F12: =west!F12*(H!E12-H!F12) -> -0.87201721 | G12: =west!G12*(H!F12-H!G12) -> -0.89327112 | H12: =west!H12*(H!G12-H!H12) -> -0.89799203 | I12: =west!I12*(H!H12-H!I12) -> -0.89836194 | J12: =west!J12*(H!I12-H!J12) -> -0.89533514 | ... M12: =west!M12*(H!L12-H!M12) -> -0.54856928
C13: =west!C13*(H!B13-H!C13) -> 0 | D13: =west!D13*(H!C13-H!D13) -> -0.37815951 | E13: =west!E13*(H!D13-H!E13) -> -0.78537239 | F13: =west!F13*(H!E13-H!F13) -> -0.87378384 | G13: =west!G13*(H!F13-H!G13) -> -0.89369462 | H13: =west!H13*(H!G13-H!H13) -> -0.89810375 | I13: =west!I13*(H!H13-H!I13) -> -0.89844914 | J13: =west!J13*(H!I13-H!J13) -> -0.8956233 | ... M13: =west!M13*(H!L13-H!M13) -> -0.56870357
C14: =west!C14*(H!B14-H!C14) -> 0 | D14: =west!D14*(H!C14-H!D14) -> -0.26193933 | E14: =west!E14*(H!D14-H!E14) -> -0.79339699 | F14: =west!F14*(H!E14-H!F14) -> -0.87623555 | G14: =west!G14*(H!F14-H!G14) -> -0.89427321 | H14: =west!H14*(H!G14-H!H14) -> -0.8982561 | I14: =west!I14*(H!H14-H!I14) -> -0.89856805 | J14: =west!J14*(H!I14-H!J14) -> -0.89601635 | ... M14: =west!M14*(H!L14-H!M14) -> -0.59765837
C15: =west!C15*(H!B15-H!C15) -> 0 | D15: =west!D15*(H!C15-H!D15) -> -0.11040459 | E15: =west!E15*(H!D15-H!E15) -> -0.80590776 | F15: =west!F15*(H!E15-H!F15) -> -0.87933527 | G15: =west!G15*(H!F15-H!G15) -> -0.89499239 | H15: =west!H15*(H!G15-H!H15) -> -0.89844519 | I15: =west!I15*(H!H15-H!I15) -> -0.89871565 | J15: =west!J15*(H!I15-H!J15) -> -0.89650398 | ... M15: =west!M15*(H!L15-H!M15) -> -0.63622916
C16: =west!C16*(H!B16-H!C16) -> 0 | D16: =west!D16*(H!C16-H!D16) -> -0.26193937 | E16: =west!E16*(H!D16-H!E16) -> -0.79339703 | F16: =west!F16*(H!E16-H!F16) -> -0.87623556 | G16: =west!G16*(H!F16-H!G16) -> -0.89427323 | H16: =west!H16*(H!G16-H!H16) -> -0.89825615 | I16: =west!I16*(H!H16-H!I16) -> -0.89856811 | J16: =west!J16*(H!I16-H!J16) -> -0.89601626 | ... M16: =west!M16*(H!L16-H!M16) -> -0.59765858
C17: =west!C17*(H!B17-H!C17) -> 0 | D17: =west!D17*(H!C17-H!D17) -> -0.37815956 | E17: =west!E17*(H!D17-H!E17) -> -0.78537245 | F17: =west!F17*(H!E17-H!F17) -> -0.87378379 | G17: =west!G17*(H!F17-H!G17) -> -0.89369458 | H17: =west!H17*(H!G17-H!H17) -> -0.89810384 | I17: =west!I17*(H!H17-H!I17) -> -0.89844919 | J17: =west!J17*(H!I17-H!J17) -> -0.89562324 | ... M17: =west!M17*(H!L17-H!M17) -> -0.56870385
C18: =west!C18*(H!B18-H!C18) -> 0 | D18: =west!D18*(H!C18-H!D18) -> -0.46030759 | E18: =west!E18*(H!D18-H!E18) -> -0.7805359 | F18: =west!F18*(H!E18-H!F18) -> -0.87201704 | G18: =west!G18*(H!F18-H!G18) -> -0.89327094 | H18: =west!H18*(H!G18-H!H18) -> -0.89799214 | I18: =west!I18*(H!H18-H!I18) -> -0.89836196 | J18: =west!J18*(H!I18-H!J18) -> -0.89533506 | ... M18: =west!M18*(H!L18-H!M18) -> -0.54856961
C19: =west!C19*(H!B19-H!C19) -> 0 | D19: =west!D19*(H!C19-H!D19) -> -0.50925334 | E19: =west!E19*(H!D19-H!E19) -> -0.77798683 | F19: =west!F19*(H!E19-H!F19) -> -0.87095264 | G19: =west!G19*(H!F19-H!G19) -> -0.89301268 | H19: =west!H19*(H!G19-H!H19) -> -0.89792396 | I19: =west!I19*(H!H19-H!I19) -> -0.8983087 | J19: =west!J19*(H!I19-H!J19) -> -0.89515919 | ... M19: =west!M19*(H!L19-H!M19) -> -0.5367048
C20: =west!C20*(H!B20-H!C20) -> 0 | D20: =west!D20*(H!C20-H!D20) -> -0.26275587 | E20: =west!E20*(H!D20-H!E20) -> -0.38859771 | F20: =west!F20*(H!E20-H!F20) -> -0.43529864 | G20: =west!G20*(H!F20-H!G20) -> -0.44646297 | H20: =west!H20*(H!G20-H!H20) -> -0.44895052 | I20: =west!I20*(H!H20-H!I20) -> -0.44914541 | J20: =west!J20*(H!I20-H!J20) -> -0.44755002 | ... M20: =west!M20*(H!L20-H!M20) -> -0.26639268

Sheet Qnorth
B2: Flux from the north
C10: =north!C10*(H!C9-H!C10) -> 0 | D10: =north!D10*(H!D9-H!D10) -> 0 | E10: =north!E10*(H!E9-H!E10) -> 0 | F10: =north!F10*(H!F9-H!F10) -> 0 | G10: =north!G10*(H!G9-H!G10) -> 0 | H10: =north!H10*(H!H9-H!H10) -> 0 | I10: =north!I10*(H!I9-H!I10) -> 0 | J10: =north!J10*(H!J9-H!J10) -> 0 | ... M10: =north!M10*(H!M9-H!M10) -> 0
C11: =north!C11*(H!C10-H!C11) -> 0 | D11: =north!D11*(H!D10-H!D11) -> 1.6258363 | E11: =north!E11*(H!E10-H!E11) -> 1.5466918 | F11: =north!F11*(H!F10-H!F11) -> 1.5111553 | G11: =north!G11*(H!G10-H!G11) -> 1.5024801 | H11: =north!H11*(H!H10-H!H11) -> 1.5001865 | I11: =north!I11*(H!I10-H!I11) -> 1.4983926 | J11: =north!J11*(H!J10-H!J11) -> 1.4924882 | ... M11: =north!M11*(H!M10-H!M11) -> 0.48359013
C12: =north!C12*(H!C11-H!C12) -> 0 | D12: =north!D12*(H!D11-H!D12) -> 4.894571 | E12: =north!E12*(H!E11-H!E12) -> 4.6396643 | F12: =north!F12*(H!F11-H!F12) -> 4.5332299 | G12: =north!G12*(H!G11-H!G12) -> 4.50741 | H12: =north!H12*(H!H11-H!H12) -> 4.5005868 | I12: =north!I12*(H!I11-H!I12) -> 4.4952614 | J12: =north!J12*(H!J11-H!J12) -> 4.4776735 | ... M12: =north!M12*(H!M11-H!M12) -> 1.4469053
C13: =north!C13*(H!C12-H!C13) -> 0 | D13: =north!D13*(H!D12-H!D13) -> 8.2148038 | E13: =north!E13*(H!E12-H!E13) -> 7.7311484 | F13: =north!F13*(H!F12-H!F13) -> 7.5544863 | G13: =north!G13*(H!G12-H!G13) -> 7.5121356 | H13: =north!H13*(H!H12-H!H13) -> 7.500964 | I13: =north!I13*(H!I12-H!I13) -> 7.4922443 | J13: =north!J13*(H!J12-H!J13) -> 7.4634276 | ... M13: =north!M13*(H!M12-H!M13) -> 2.3983382
C14: =north!C14*(H!C13-H!C14) -> 0 | D14: =north!D14*(H!D13-H!D14) -> 11.622017 | E14: =north!E14*(H!E13-H!E14) -> 10.819557 | F14: =north!F14*(H!F13-H!F14) -> 10.574385 | G14: =north!G14*(H!G13-H!G14) -> 10.516526 | H14: =north!H14*(H!H13-H!H14) -> 10.50129 | I14: =north!I14*(H!I13-H!I14) -> 10.489399 | J14: =north!J14*(H!J13-H!J14) -> 10.450094 | ... M14: =north!M14*(H!M13-H!M14) -> 3.3296136
C15: =north!C15*(H!C14-H!C15) -> 0 | D15: =north!D15*(H!D14-H!D15) -> 15.153474 | E15: =north!E15*(H!E14-H!E15) -> 13.902398 | F15: =north!F15*(H!F14-H!F15) -> 13.592426 | G15: =north!G15*(H!G14-H!G15) -> 13.520509 | H15: =north!H15*(H!H14-H!H15) -> 13.5016 | I15: =north!I15*(H!I14-H!I15) -> 13.48684 | J15: =north!J15*(H!J14-H!J15) -> 13.438078 | ... M15: =north!M15*(H!M14-H!M15) -> 4.2319566
C16: =north!C16*(H!C15-H!C16) -> 0 | D16: =north!D16*(H!D15-H!D16) -> -15.153478 | E16: =north!E16*(H!E15-H!E16) -> -13.902405 | F16: =north!F16*(H!F15-H!F16) -> -13.592434 | G16: =north!G16*(H!G15-H!G16) -> -13.520518 | H16: =north!H16*(H!H15-H!H16) -> -13.501613 | I16: =north!I16*(H!I15-H!I16) -> -13.48686 | J16: =north!J16*(H!J15-H!J16) -> -13.438088 | ... M16: =north!M16*(H!M15-H!M16) -> -4.2319828
C17: =north!C17*(H!C16-H!C17) -> 0 | D17: =north!D17*(H!D16-H!D17) -> -11.622019 | E17: =north!E17*(H!E16-H!E17) -> -10.819561 | F17: =north!F17*(H!F16-H!F17) -> -10.574385 | G17: =north!G17*(H!G16-H!G17) -> -10.516521 | H17: =north!H17*(H!H16-H!H17) -> -10.50129 | I17: =north!I17*(H!I16-H!I17) -> -10.489397 | J17: =north!J17*(H!J16-H!J17) -> -10.450096 | ... M17: =north!M17*(H!M16-H!M17) -> -3.3296261
C18: =north!C18*(H!C17-H!C18) -> 0 | D18: =north!D18*(H!D17-H!D18) -> -8.214803 | E18: =north!E18*(H!E17-H!E18) -> -7.7311475 | F18: =north!F18*(H!F17-H!F18) -> -7.5544725 | G18: =north!G18*(H!G17-H!G18) -> -7.5121082 | H18: =north!H18*(H!H17-H!H18) -> -7.5009385 | I18: =north!I18*(H!I17-H!I18) -> -7.4922155 | J18: =north!J18*(H!J17-H!J18) -> -7.4633977 | ... M18: =north!M18*(H!M17-H!M18) -> -2.3983279
C19: =north!C19*(H!C18-H!C19) -> 0 | D19: =north!D19*(H!D18-H!D19) -> -4.8945743 | E19: =north!E19*(H!E18-H!E19) -> -4.6396682 | F19: =north!F19*(H!F18-H!F19) -> -4.5332274 | G19: =north!G19*(H!G18-H!G19) -> -4.5074016 | H19: =north!H19*(H!H18-H!H19) -> -4.5005832 | I19: =north!I19*(H!I18-H!I19) -> -4.4952572 | J19: =north!J19*(H!J18-H!J19) -> -4.47767 | ... M19: =north!M19*(H!M18-H!M19) -> -1.4469136
